Workbook
Name AR_Customers: 'Analysis'!$V$170:$V$177
Name AR_Sales: 'Analysis'!$W$170:$W$176

Sheet Dashboard
B1: ACCOUNTS RECEIVABLE DASHBOARD | N1: Client Filter | P1: All | AA1: =IF(Analysis!D7=0,AD1,"") | AB1: =IF(Analysis!D7>0,AD1,"") | AC1: =IF(Analysis!D7<0,AD1,"") -> -0.05B (-0.8%) | AD1: =TEXT(Analysis!D7/1000000000,"+0.00;-0.00;0.00")&"B ("&TEXT(Analysis!E7,"+0.0%;-0.0%;0.0%")&")" -> -0.05B (-0.8%) | AE1: ="Current: "&TEXT(Analysis!B7/1000000000,"0.00")&"B VND" -> Current: 5.78B VND | AF1: ="Prior: "&TEXT(Analysis!C7/1000000000,"0.00")&"B VND" -> Prior: 5.83B VND | AG1: Overdue Ratio (1–60 Days) | AH1: =TEXT(Analysis!B16,"0.0%") -> 11.3%
B2: Report Date: | D2: 46300 | N2: Sales Rep Filter | P2: All | AA2: =IF(Analysis!D8=0,AD2,"") | AB2: =IF(Analysis!D8>0,AD2,"") | AC2: =IF(Analysis!D8<0,AD2,"") -> -0.08B (-1.9%) | AD2: =TEXT(Analysis!D8/1000000000,"+0.00;-0.00;0.00")&"B ("&TEXT(Analysis!E8,"+0.0%;-0.0%;0.0%")&")" -> -0.08B (-1.9%) | AE2: ="Current: "&TEXT(Analysis!B8/1000000000,"0.00")&"B VND" -> Current: 4.02B VND | AF2: ="Prior: "&TEXT(Analysis!C8/1000000000,"0.00")&"B VND" -> Prior: 4.10B VND | AG2: Receivables Ratio (>60 Days) | AH2: =TEXT(Analysis!B17,"0.0%") -> 7.9%
B3: Current and prior invoice records. Public demonstration workbook. | N3: Status Filter | P3: All | AA3: =IF(Analysis!D9=0,AD3,"") | AB3: =IF(Analysis!D9>0,AD3,"") | AC3: =IF(Analysis!D9<0,AD3,"") -> -0.13B (-1.3%) | AD3: =TEXT(Analysis!D9/1000000000,"+0.00;-0.00;0.00")&"B ("&TEXT(Analysis!E9,"+0.0%;-0.0%;0.0%")&")" -> -0.13B (-1.3%) | AE3: ="Current: "&TEXT(Analysis!B9/1000000000,"0.00")&"B VND" -> Current: 9.80B VND | AF3: ="Prior: "&TEXT(Analysis!C9/1000000000,"0.00")&"B VND" -> Prior: 9.93B VND | AG3: Total Overdue Ratio | AH3: =TEXT(Analysis!B18,"0.0%") -> 19.2%
B6: Total Outstanding AR | E6: Avg Overdue Days | G6: >60d / Total Overdue | I6: Top Client Share | K6: Top 3 Clients Share | N6: Due in Next 10 Days | Z6: ='Analysis'!D6 -> 1.7123355e+10
B7: =TEXT(Analysis!B6/1000000000,"0.00")&"B VND" -> 51.06B VND | E7: =TEXT(Analysis!B56,"0.0")&" Days" -> 39.5 Days | G7: =TEXT(Analysis!B57,"0.0%") -> 41.0% | I7: =TEXT(Analysis!B58,"0.0%") -> 76.5% | K7: =TEXT(Analysis!B59,"0.0%") -> 91.5% | N7: =TEXT(Analysis!B11/1000000000,"0.00")&"B VND" -> 3.81B VND
B9: ="Prior: "&TEXT(Analysis!C6/1000000000,"0.00")&"B VND" -> Prior: 33.93B VND | E9: ="Prior: "&TEXT(Analysis!C56,"0.0")&" Days" -> Prior: 40.0 Days | G9: ="Prior: "&TEXT(Analysis!C57,"0.0%") -> Prior: 41.3% | I9: ="Prior: "&TEXT(Analysis!C58,"0.0%") -> Prior: 69.9% | K9: ="Prior: "&TEXT(Analysis!C59,"0.0%") -> Prior: 95.3% | N9: ="Prior: "&TEXT(Analysis!C11/1000000000,"0.00")&"B VND" -> Prior: 3.35B VND
B10: =TEXT('Analysis'!D6/1000000000,"+0.00;-0.00;0.00")&"B ("&TEXT('Analysis'!E6,"+0.0%;-0.0%;0.0%")&")" -> +17.12B (+50.5%) | E10: =TEXT('Analysis'!D56,"+0.0;-0.0;0.0")&" Days ("&TEXT('Analysis'!E56,"+0.0%;-0.0%;0.0%")&")" -> -0.5 Days (-1.3%) | G10: =TEXT('Analysis'!D57*100,"+0.0;-0.0;0.0")&" pp" -> -0.3 pp | I10: =TEXT('Analysis'!D58*100,"+0.0;-0.0;0.0")&" pp" -> +6.6 pp | K10: =TEXT('Analysis'!D59*100,"+0.0;-0.0;0.0")&" pp" -> -3.7 pp | N10: =TEXT('Analysis'!D11/1000000000,"+0.00;-0.00;0.00")&"B ("&TEXT('Analysis'!E11,"+0.0%;-0.0%;0.0%")&")" -> +0.47B (+13.9%)
Z11: ='Analysis'!D11 -> 4.6513087e+08
B12: Overdue Ratio (1–60 Days) | G12: Receivables Ratio (>60 Days) | K12: Total Overdue Ratio
B21: =TEXT('Analysis'!B16,"0.0%") -> 11.3% | G21: =TEXT('Analysis'!B17,"0.0%") -> 7.9% | K21: =TEXT('Analysis'!B18,"0.0%") -> 19.2%
B22: ="Current: "&TEXT('Analysis'!B7/1000000000,"0.00")&" B VND" -> Current: 5.52B VND | G22: ="Current: "&TEXT('Analysis'!B8/1000000000,"0.00")&" B VND" -> Current: 3.84B VND | K22: ="Current: "&TEXT('Analysis'!B9/1000000000,"0.00")&" B VND" -> Current: 9.36B VND
B27: Customer/staff filters apply to the overview. Status also filters the charts and collection list.
B28: 98 current invoices. All customer and staff groups reconcile to the current ledger total.
Z56: ='Analysis'!D56 -> -0.52699735
Z57: ='Analysis'!D57 -> -0.0026233793
Z58: ='Analysis'!D58 -> 0.065755063
Z59: ='Analysis'!D59 -> -0.037499327
B69: Client Account | D69: Current Balance | F69: Prior Balance | G69: In-Term Debt | H69: Overdue Debt | J69: Sales Representative | K69: Current Balance | L69: Prior Balance | N69: In-Term Debt | P69: Overdue Debt
B70: Client Beta (Heavy Const.) | D70: ='Analysis'!B170 -> 2.000343e+09 | F70: ='Analysis'!C170 -> 1.6031727e+09 | G70: ='Analysis'!D170 -> 4.50339e+08 | H70: ='Analysis'!E170 -> 1.550004e+09 | J70: Senior Sales Rep 1 | K70: ='Analysis'!H170 -> 1.4614668e+10 | L70: ='Analysis'!I170 -> 1.4415883e+10 | N70: ='Analysis'!J170 -> 1.0509252e+10 | P70: ='Analysis'!K170 -> 4.105416e+09
B71: Client Delta (Commercial Facade) | D71: ='Analysis'!B171 -> 2.283114e+09 | F71: ='Analysis'!C171 -> 0 | G71: ='Analysis'!D171 -> 2.283114e+09 | H71: ='Analysis'!E171 -> 0 | J71: Senior Sales Rep 2 | K71: ='Analysis'!H171 -> 3.0092673e+10 | L71: ='Analysis'!I171 -> 1.5416999e+10 | N71: ='Analysis'!J171 -> 2.8416993e+10 | P71: ='Analysis'!K171 -> 1.67568e+09
B72: Client Alpha (Steel EPC) | D72: ='Analysis'!B172 -> 3.9053817e+10 | F72: ='Analysis'!C172 -> 2.3724533e+10 | G72: ='Analysis'!D172 -> 3.6498405e+10 | H72: ='Analysis'!E172 -> 2.555412e+09 | J72: Sales Rep 6 | K72: ='Analysis'!H172 -> 0 | L72: ='Analysis'!I172 -> 0 | N72: ='Analysis'!J172 -> 0 | P72: ='Analysis'!K172 -> 0
B73: Client Alpha Sub-Contract | D73: ='Analysis'!B173 -> 3.6531814e+09 | F73: ='Analysis'!C173 -> 4.5051769e+09 | G73: ='Analysis'!D173 -> 1.9775014e+09 | H73: ='Analysis'!E173 -> 1.67568e+09 | J73: Sales Rep 4 | K73: ='Analysis'!H173 -> 43462950 | L73: ='Analysis'!I173 -> 0 | N73: ='Analysis'!J173 -> 43462950 | P73: ='Analysis'!K173 -> 0
B74: Client Epsilon (Equipment) | D74: ='Analysis'!B174 -> 43462950 | F74: ='Analysis'!C174 -> 0 | G74: ='Analysis'!D174 -> 43462950 | H74: ='Analysis'!E174 -> 0 | J74: Sales Rep 5 | K74: ='Analysis'!H174 -> 324663 | L74: ='Analysis'!I174 -> 333943.13 | N74: ='Analysis'!J174 -> 324663 | P74: ='Analysis'!K174 -> 0
B75: Client Zeta (Building Tech) | D75: ='Analysis'!B175 -> 324663 | F75: ='Analysis'!C175 -> 333943.13 | G75: ='Analysis'!D175 -> 324663 | H75: ='Analysis'!E175 -> 0 | J75: Sales Rep 3 | K75: ='Analysis'!H175 -> 4.021632e+09 | L75: ='Analysis'!I175 -> 4.0993038e+09 | N75: ='Analysis'!J175 -> 0 | P75: ='Analysis'!K175 -> 4.021632e+09
B76: Client Gamma (Offshore Energy) | D76: ='Analysis'!B176 -> 4.021632e+09 | F76: ='Analysis'!C176 -> 4.0993038e+09 | G76: ='Analysis'!D176 -> 0 | H76: ='Analysis'!E176 -> 4.021632e+09

Sheet Current AR
A1: Current-period invoice ledger. Names, identifiers and financial amounts have been changed for publication.
D3: 46300
A5: Customer | B5: Legal Name | C5: Document Number | D5: Invoice Number | E5: Invoice Date | F5: Due Date | G5: Invoice Gross Amount | H5: Receipts Applied | I5: Outstanding Balance | J5: Sales Representative | K5: Business Type | L5: Project | M5: Description | N5: Promised Payment Date | O5: Last Contact | P5: Next Action | Q5: Days Overdue | R5: Customer / Staff Match | S5: Selected Balance | T5: Selected Overdue | U5: Status Match | V5: Filtered Balance | W5: Overdue Days × Balance | Y5: Stable Document Key
A6: Client Beta (Heavy Const.) | B6: CLIENT BETA HEAVY INDUSTRIAL CONSTRUCTION CORP | C6: AR-00001 | D6: 70000001 | E6: 46262 | F6: 46292 | G6: 75501400 | H6: 0 | I6: 75501400 | J6: Senior Sales Rep 1 | K6: Trading | L6: Project 002 | M6: Collection note 001 | Q6: =IF(ISNUMBER(F6),Dashboard!$D$2-F6,"") -> 8 | R6: =IF(AND(OR(Dashboard!$P$1="All",A6=Dashboard!$P$1),OR(Dashboard!$P$2="All",J6=Dashboard!$P$2)),1,0) -> 1 | S6: =I6*R6 -> 75501400 | T6: =IF(AND(ISNUMBER(Q6),Q6>0),S6,0) -> 75501400 | U6: =IF(OR(Dashboard!$P$3="All",AND(Dashboard!$P$3="Not due",Q6<0),AND(Dashboard!$P$3="Due in 10 days",Q6>=-10,Q6<=0),AND(Dashboard!$P$3="Due in 30 days",Q6>=-30,Q6<=0),AND(Dashboard!$P$3="Overdue 1–60 days",Q6>0,Q6<=60),AND(Dashboard!$P$3="Over 60 days",Q6>60),AND(Dashboard!$P$3="All overdue",Q6>0)),1,0) -> 1 | V6: =S6*U6 -> 75501400 | W6: =IF(Q6>0,T6*Q6,0) -> 604011200 | X6: =IF(V6>0,COUNTIF($V$6:V6,">0"),"") -> 1 | Y6: =C6&"|"&D6 -> AR-00001|70000001 | AA6: ["Demo Company 265", "AR-00001", "70000001", "2026-08-28"]
A7: Client Beta (Heavy Const.) | B7: CLIENT BETA HEAVY INDUSTRIAL CONSTRUCTION CORP | C7: AR-00002 | D7: 70000002 | E7: 46262 | F7: 46292 | G7: 920560752 | H7: 0 | I7: 920560752 | J7: Senior Sales Rep 1 | K7: Trading | L7: Project 003 | M7: Collection note 001 | Q7: =IF(ISNUMBER(F7),Dashboard!$D$2-F7,"") -> 8 | R7: =IF(AND(OR(Dashboard!$P$1="All",A7=Dashboard!$P$1),OR(Dashboard!$P$2="All",J7=Dashboard!$P$2)),1,0) -> 1 | S7: =I7*R7 -> 920560752 | T7: =IF(AND(ISNUMBER(Q7),Q7>0),S7,0) -> 920560752 | U7: =IF(OR(Dashboard!$P$3="All",AND(Dashboard!$P$3="Not due",Q7<0),AND(Dashboard!$P$3="Due in 10 days",Q7>=-10,Q7<=0),AND(Dashboard!$P$3="Due in 30 days",Q7>=-30,Q7<=0),AND(Dashboard!$P$3="Overdue 1–60 days",Q7>0,Q7<=60),AND(Dashboard!$P$3="Over 60 days",Q7>60),AND(Dashboard!$P$3="All overdue",Q7>0)),1,0) -> 1 | V7: =S7*U7 -> 920560752 | W7: =IF(Q7>0,T7*Q7,0) -> 7364486016 | X7: =IF(V7>0,COUNTIF($V$6:V7,">0"),"") -> 2 | Y7: =C7&"|"&D7 -> AR-00002|70000002 | AA7: ["Demo Company 265", "AR-00002", "70000002", "2026-08-28"]
A8: Client Beta (Heavy Const.) | B8: CLIENT BETA HEAVY INDUSTRIAL CONSTRUCTION CORP | C8: AR-00003 | D8: 70000003 | E8: 46262 | F8: 46292 | G8: 553941849 | H8: 0 | I8: 553941849 | J8: Senior Sales Rep 1 | K8: Trading | L8: Project 004 | M8: Collection note 001 | Q8: =IF(ISNUMBER(F8),Dashboard!$D$2-F8,"") -> 8 | R8: =IF(AND(OR(Dashboard!$P$1="All",A8=Dashboard!$P$1),OR(Dashboard!$P$2="All",J8=Dashboard!$P$2)),1,0) -> 1 | S8: =I8*R8 -> 553941849 | T8: =IF(AND(ISNUMBER(Q8),Q8>0),S8,0) -> 553941849 | U8: =IF(OR(Dashboard!$P$3="All",AND(Dashboard!$P$3="Not due",Q8<0),AND(Dashboard!$P$3="Due in 10 days",Q8>=-10,Q8<=0),AND(Dashboard!$P$3="Due in 30 days",Q8>=-30,Q8<=0),AND(Dashboard!$P$3="Overdue 1–60 days",Q8>0,Q8<=60),AND(Dashboard!$P$3="Over 60 days",Q8>60),AND(Dashboard!$P$3="All overdue",Q8>0)),1,0) -> 1 | V8: =S8*U8 -> 553941849 | W8: =IF(Q8>0,T8*Q8,0) -> 4431534792 | X8: =IF(V8>0,COUNTIF($V$6:V8,">0"),"") -> 3 | Y8: =C8&"|"&D8 -> AR-00003|70000003 | AA8: ["Demo Company 265", "AR-00003", "70000003", "2026-08-28"]
A9: Client Beta (Heavy Const.) | B9: CLIENT BETA HEAVY INDUSTRIAL CONSTRUCTION CORP | C9: AR-00004 | D9: 70000004 | E9: 46294 | F9: 46324 | G9: 450339000 | H9: 0 | I9: 450339000 | J9: Senior Sales Rep 1 | K9: Trading | L9: Project 005 | M9: Collection note 001 | Q9: =IF(ISNUMBER(F9),Dashboard!$D$2-F9,"") -> -24 | R9: =IF(AND(OR(Dashboard!$P$1="All",A9=Dashboard!$P$1),OR(Dashboard!$P$2="All",J9=Dashboard!$P$2)),1,0) -> 1 | S9: =I9*R9 -> 450339000 | T9: =IF(AND(ISNUMBER(Q9),Q9>0),S9,0) -> 0 | U9: =IF(OR(Dashboard!$P$3="All",AND(Dashboard!$P$3="Not due",Q9<0),AND(Dashboard!$P$3="Due in 10 days",Q9>=-10,Q9<=0),AND(Dashboard!$P$3="Due in 30 days",Q9>=-30,Q9<=0),AND(Dashboard!$P$3="Overdue 1–60 days",Q9>0,Q9<=60),AND(Dashboard!$P$3="Over 60 days",Q9>60),AND(Dashboard!$P$3="All overdue",Q9>0)),1,0) -> 1 | V9: =S9*U9 -> 450339000 | W9: =IF(Q9>0,T9*Q9,0) -> 0 | X9: =IF(V9>0,COUNTIF($V$6:V9,">0"),"") -> 4 | Y9: =C9&"|"&D9 -> AR-00004|70000004 | AA9: ["Demo Company 265", "AR-00004", "70000004", "2026-09-29"]
A10: Client Delta (Commercial Facade) | B10: CLIENT DELTA COMMERCIAL FACADES LTD | C10: AR-00005 | D10: 70000005 | E10: 46289 | F10: 46349 | G10: 1821258559 | H10: 0 | I10: 1821258559 | J10: Sales Rep 6 | K10: Trading | M10: Collection note 002 | Q10: =IF(ISNUMBER(F10),Dashboard!$D$2-F10,"") -> -49 | R10: =IF(AND(OR(Dashboard!$P$1="All",A10=Dashboard!$P$1),OR(Dashboard!$P$2="All",J10=Dashboard!$P$2)),1,0) -> 1 | S10: =I10*R10 -> 1821258559 | T10: =IF(AND(ISNUMBER(Q10),Q10>0),S10,0) -> 0 | U10: =IF(OR(Dashboard!$P$3="All",AND(Dashboard!$P$3="Not due",Q10<0),AND(Dashboard!$P$3="Due in 10 days",Q10>=-10,Q10<=0),AND(Dashboard!$P$3="Due in 30 days",Q10>=-30,Q10<=0),AND(Dashboard!$P$3="Overdue 1–60 days",Q10>0,Q10<=60),AND(Dashboard!$P$3="Over 60 days",Q10>60),AND(Dashboard!$P$3="All overdue",Q10>0)),1,0) -> 1 | V10: =S10*U10 -> 1821258559 | W10: =IF(Q10>0,T10*Q10,0) -> 0 | X10: =IF(V10>0,COUNTIF($V$6:V10,">0"),"") -> 5 | Y10: =C10&"|"&D10 -> AR-00005|70000005 | AA10: ["Demo Company 045", "AR-00005", "70000005", "2026-09-24"]
A11: Client Delta (Commercial Facade) | B11: CLIENT DELTA COMMERCIAL FACADES LTD | C11: AR-00006 | D11: 70000006 | E11: 46294 | F11: 46354 | G11: 149214834 | H11: 0 | I11: 149214834 | J11: Sales Rep 6 | K11: Trading | M11: Collection note 003 | Q11: =IF(ISNUMBER(F11),Dashboard!$D$2-F11,"") -> -54 | R11: =IF(AND(OR(Dashboard!$P$1="All",A11=Dashboard!$P$1),OR(Dashboard!$P$2="All",J11=Dashboard!$P$2)),1,0) -> 1 | S11: =I11*R11 -> 149214834 | T11: =IF(AND(ISNUMBER(Q11),Q11>0),S11,0) -> 0 | U11: =IF(OR(Dashboard!$P$3="All",AND(Dashboard!$P$3="Not due",Q11<0),AND(Dashboard!$P$3="Due in 10 days",Q11>=-10,Q11<=0),AND(Dashboard!$P$3="Due in 30 days",Q11>=-30,Q11<=0),AND(Dashboard!$P$3="Overdue 1–60 days",Q11>0,Q11<=60),AND(Dashboard!$P$3="Over 60 days",Q11>60),AND(Dashboard!$P$3="All overdue",Q11>0)),1,0) -> 1 | V11: =S11*U11 -> 149214834 | W11: =IF(Q11>0,T11*Q11,0) -> 0 | X11: =IF(V11>0,COUNTIF($V$6:V11,">0"),"") -> 6 | Y11: =C11&"|"&D11 -> AR-00006|70000006 | AA11: ["Demo Company 045", "AR-00006", "70000006", "2026-09-29"]
A12: Client Delta (Commercial Facade) | B12: CLIENT DELTA COMMERCIAL FACADES LTD | C12: AR-00007 | D12: 70000007 | E12: 46294 | F12: 46354 | G12: 28421874 | H12: 0 | I12: 28421874 | J12: Sales Rep 6 | K12: Trading | M12: Collection note 003 | Q12: =IF(ISNUMBER(F12),Dashboard!$D$2-F12,"") -> -54 | R12: =IF(AND(OR(Dashboard!$P$1="All",A12=Dashboard!$P$1),OR(Dashboard!$P$2="All",J12=Dashboard!$P$2)),1,0) -> 1 | S12: =I12*R12 -> 28421874 | T12: =IF(AND(ISNUMBER(Q12),Q12>0),S12,0) -> 0 | U12: =IF(OR(Dashboard!$P$3="All",AND(Dashboard!$P$3="Not due",Q12<0),AND(Dashboard!$P$3="Due in 10 days",Q12>=-10,Q12<=0),AND(Dashboard!$P$3="Due in 30 days",Q12>=-30,Q12<=0),AND(Dashboard!$P$3="Overdue 1–60 days",Q12>0,Q12<=60),AND(Dashboard!$P$3="Over 60 days",Q12>60),AND(Dashboard!$P$3="All overdue",Q12>0)),1,0) -> 1 | V12: =S12*U12 -> 28421874 | W12: =IF(Q12>0,T12*Q12,0) -> 0 | X12: =IF(V12>0,COUNTIF($V$6:V12,">0"),"") -> 7 | Y12: =C12&"|"&D12 -> AR-00007|70000007 | AA12: ["Demo Company 045", "AR-00007", "70000007", "2026-09-29"]
A13: Client Delta (Commercial Facade) | B13: CLIENT DELTA COMMERCIAL FACADES LTD | C13: AR-00008 | D13: 70000008 | E13: 46298 | F13: 46358 | G13: 284218732 | H13: 0 | I13: 284218732 | J13: Sales Rep 6 | K13: Trading | L13: Project 002 | M13: Collection note 004 | Q13: =IF(ISNUMBER(F13),Dashboard!$D$2-F13,"") -> -58 | R13: =IF(AND(OR(Dashboard!$P$1="All",A13=Dashboard!$P$1),OR(Dashboard!$P$2="All",J13=Dashboard!$P$2)),1,0) -> 1 | S13: =I13*R13 -> 284218732 | T13: =IF(AND(ISNUMBER(Q13),Q13>0),S13,0) -> 0 | U13: =IF(OR(Dashboard!$P$3="All",AND(Dashboard!$P$3="Not due",Q13<0),AND(Dashboard!$P$3="Due in 10 days",Q13>=-10,Q13<=0),AND(Dashboard!$P$3="Due in 30 days",Q13>=-30,Q13<=0),AND(Dashboard!$P$3="Overdue 1–60 days",Q13>0,Q13<=60),AND(Dashboard!$P$3="Over 60 days",Q13>60),AND(Dashboard!$P$3="All overdue",Q13>0)),1,0) -> 1 | V13: =S13*U13 -> 284218732 | W13: =IF(Q13>0,T13*Q13,0) -> 0 | X13: =IF(V13>0,COUNTIF($V$6:V13,">0"),"") -> 8 | Y13: =C13&"|"&D13 -> AR-00008|70000008 | AA13: ["Demo Company 045", "AR-00008", "70000008", "2026-10-03"]
A14: Client Alpha (Steel EPC) | B14: CLIENT ALPHA STEEL STRUCTURE CORPORATION | C14: AR-00009 | D14: 70000009 | E14: 46189 | F14: 46264 | G14: 91483402 | H14: 0 | I14: 91483402 | J14: Senior Sales Rep 1 | K14: Trading | L14: Project 003 | M14: Collection note 005 | Q14: =IF(ISNUMBER(F14),Dashboard!$D$2-F14,"") -> 36 | R14: =IF(AND(OR(Dashboard!$P$1="All",A14=Dashboard!$P$1),OR(Dashboard!$P$2="All",J14=Dashboard!$P$2)),1,0) -> 1 | S14: =I14*R14 -> 91483402 | T14: =IF(AND(ISNUMBER(Q14),Q14>0),S14,0) -> 91483402 | U14: =IF(OR(Dashboard!$P$3="All",AND(Dashboard!$P$3="Not due",Q14<0),AND(Dashboard!$P$3="Due in 10 days",Q14>=-10,Q14<=0),AND(Dashboard!$P$3="Due in 30 days",Q14>=-30,Q14<=0),AND(Dashboard!$P$3="Overdue 1–60 days",Q14>0,Q14<=60),AND(Dashboard!$P$3="Over 60 days",Q14>60),AND(Dashboard!$P$3="All overdue",Q14>0)),1,0) -> 1 | V14: =S14*U14 -> 91483402 | W14: =IF(Q14>0,T14*Q14,0) -> 3293402472 | X14: =IF(V14>0,COUNTIF($V$6:V14,">0"),"") -> 9 | Y14: =C14&"|"&D14 -> AR-00009|70000009 | AA14: ["Demo Company 010", "AR-00009", "70000009", "2026-06-16"]
A15: Client Alpha (Steel EPC) | B15: CLIENT ALPHA STEEL STRUCTURE CORPORATION | C15: AR-00010 | D15: 70000010 | E15: 46191 | F15: 46266 | G15: 454201191 | H15: 0 | I15: 454201191 | J15: Senior Sales Rep 1 | K15: Trading | L15: Project 004 | M15: Collection note 006 | Q15: =IF(ISNUMBER(F15),Dashboard!$D$2-F15,"") -> 34 | R15: =IF(AND(OR(Dashboard!$P$1="All",A15=Dashboard!$P$1),OR(Dashboard!$P$2="All",J15=Dashboard!$P$2)),1,0) -> 1 | S15: =I15*R15 -> 454201191 | T15: =IF(AND(ISNUMBER(Q15),Q15>0),S15,0) -> 454201191 | U15: =IF(OR(Dashboard!$P$3="All",AND(Dashboard!$P$3="Not due",Q15<0),AND(Dashboard!$P$3="Due in 10 days",Q15>=-10,Q15<=0),AND(Dashboard!$P$3="Due in 30 days",Q15>=-30,Q15<=0),AND(Dashboard!$P$3="Overdue 1–60 days",Q15>0,Q15<=60),AND(Dashboard!$P$3="Over 60 days",Q15>60),AND(Dashboard!$P$3="All overdue",Q15>0)),1,0) -> 1 | V15: =S15*U15 -> 454201191 | W15: =IF(Q15>0,T15*Q15,0) -> 15442840494 | X15: =IF(V15>0,COUNTIF($V$6:V15,">0"),"") -> 10 | Y15: =C15&"|"&D15 -> AR-00010|70000010 | AA15: ["Demo Company 010", "AR-00010", "70000010", "2026-06-18"]
A16: Client Alpha (Steel EPC) | B16: CLIENT ALPHA STEEL STRUCTURE CORPORATION | C16: AR-00011 | D16: 70000011 | E16: 46197 | F16: 46272 | G16: 114561937 | H16: 0 | I16: 114561937 | J16: Senior Sales Rep 1 | K16: Trading | L16: Project 005 | M16: Collection note 007 | Q16: =IF(ISNUMBER(F16),Dashboard!$D$2-F16,"") -> 28 | R16: =IF(AND(OR(Dashboard!$P$1="All",A16=Dashboard!$P$1),OR(Dashboard!$P$2="All",J16=Dashboard!$P$2)),1,0) -> 1 | S16: =I16*R16 -> 114561937 | T16: =IF(AND(ISNUMBER(Q16),Q16>0),S16,0) -> 114561937 | U16: =IF(OR(Dashboard!$P$3="All",AND(Dashboard!$P$3="Not due",Q16<0),AND(Dashboard!$P$3="Due in 10 days",Q16>=-10,Q16<=0),AND(Dashboard!$P$3="Due in 30 days",Q16>=-30,Q16<=0),AND(Dashboard!$P$3="Overdue 1–60 days",Q16>0,Q16<=60),AND(Dashboard!$P$3="Over 60 days",Q16>60),AND(Dashboard!$P$3="All overdue",Q16>0)),1,0) -> 1 | V16: =S16*U16 -> 114561937 | W16: =IF(Q16>0,T16*Q16,0) -> 3207734236 | X16: =IF(V16>0,COUNTIF($V$6:V16,">0"),"") -> 11 | Y16: =C16&"|"&D16 -> AR-00011|70000011 | AA16: ["Demo Company 010", "AR-00011", "70000011", "2026-06-24"]
A17: Client Alpha (Steel EPC) | B17: CLIENT ALPHA STEEL STRUCTURE CORPORATION | C17: AR-00012 | D17: 70000012 | E17: 46210 | F17: 46285 | G17: 54738470 | H17: 0 | I17: 54738470 | J17: Senior Sales Rep 1 | K17: Trading | L17: Project 006 | M17: Collection note 008 | Q17: =IF(ISNUMBER(F17),Dashboard!$D$2-F17,"") -> 15 | R17: =IF(AND(OR(Dashboard!$P$1="All",A17=Dashboard!$P$1),OR(Dashboard!$P$2="All",J17=Dashboard!$P$2)),1,0) -> 1 | S17: =I17*R17 -> 54738470 | T17: =IF(AND(ISNUMBER(Q17),Q17>0),S17,0) -> 54738470 | U17: =IF(OR(Dashboard!$P$3="All",AND(Dashboard!$P$3="Not due",Q17<0),AND(Dashboard!$P$3="Due in 10 days",Q17>=-10,Q17<=0),AND(Dashboard!$P$3="Due in 30 days",Q17>=-30,Q17<=0),AND(Dashboard!$P$3="Overdue 1–60 days",Q17>0,Q17<=60),AND(Dashboard!$P$3="Over 60 days",Q17>60),AND(Dashboard!$P$3="All overdue",Q17>0)),1,0) -> 1 | V17: =S17*U17 -> 54738470 | W17: =IF(Q17>0,T17*Q17,0) -> 821077050 | X17: =IF(V17>0,COUNTIF($V$6:V17,">0"),"") -> 12 | Y17: =C17&"|"&D17 -> AR-00012|70000012 | AA17: ["Demo Company 010", "AR-00012", "70000012", "2026-07-07"]
A18: Client Alpha (Steel EPC) | B18: CLIENT ALPHA STEEL STRUCTURE CORPORATION | C18: AR-00013 | D18: 70000013 | E18: 46210 | F18: 46285 | G18: 867074591 | H18: 0 | I18: 867074591 | J18: Senior Sales Rep 1 | K18: Trading | L18: Project 007 | M18: Collection note 008 | Q18: =IF(ISNUMBER(F18),Dashboard!$D$2-F18,"") -> 15 | R18: =IF(AND(OR(Dashboard!$P$1="All",A18=Dashboard!$P$1),OR(Dashboard!$P$2="All",J18=Dashboard!$P$2)),1,0) -> 1 | S18: =I18*R18 -> 867074591 | T18: =IF(AND(ISNUMBER(Q18),Q18>0),S18,0) -> 867074591 | U18: =IF(OR(Dashboard!$P$3="All",AND(Dashboard!$P$3="Not due",Q18<0),AND(Dashboard!$P$3="Due in 10 days",Q18>=-10,Q18<=0),AND(Dashboard!$P$3="Due in 30 days",Q18>=-30,Q18<=0),AND(Dashboard!$P$3="Overdue 1–60 days",Q18>0,Q18<=60),AND(Dashboard!$P$3="Over 60 days",Q18>60),AND(Dashboard!$P$3="All overdue",Q18>0)),1,0) -> 1 | V18: =S18*U18 -> 867074591 | W18: =IF(Q18>0,T18*Q18,0) -> 13006118865 | X18: =IF(V18>0,COUNTIF($V$6:V18,">0"),"") -> 13 | Y18: =C18&"|"&D18 -> AR-00013|70000013 | AA18: ["Demo Company 010", "AR-00013", "70000013", "2026-07-07"]
A19: Client Alpha (Steel EPC) | B19: CLIENT ALPHA STEEL STRUCTURE CORPORATION | C19: AR-00014 | D19: 70000014 | E19: 46210 | F19: 46285 | G19: 21434303 | H19: 0 | I19: 21434303 | J19: Senior Sales Rep 1 | K19: Trading | L19: Project 008 | M19: Collection note 008 | Q19: =IF(ISNUMBER(F19),Dashboard!$D$2-F19,"") -> 15 | R19: =IF(AND(OR(Dashboard!$P$1="All",A19=Dashboard!$P$1),OR(Dashboard!$P$2="All",J19=Dashboard!$P$2)),1,0) -> 1 | S19: =I19*R19 -> 21434303 | T19: =IF(AND(ISNUMBER(Q19),Q19>0),S19,0) -> 21434303 | U19: =IF(OR(Dashboard!$P$3="All",AND(Dashboard!$P$3="Not due",Q19<0),AND(Dashboard!$P$3="Due in 10 days",Q19>=-10,Q19<=0),AND(Dashboard!$P$3="Due in 30 days",Q19>=-30,Q19<=0),AND(Dashboard!$P$3="Overdue 1–60 days",Q19>0,Q19<=60),AND(Dashboard!$P$3="Over 60 days",Q19>60),AND(Dashboard!$P$3="All overdue",Q19>0)),1,0) -> 1 | V19: =S19*U19 -> 21434303 | W19: =IF(Q19>0,T19*Q19,0) -> 321514545 | X19: =IF(V19>0,COUNTIF($V$6:V19,">0"),"") -> 14 | Y19: =C19&"|"&D19 -> AR-00014|70000014 | AA19: ["Demo Company 010", "AR-00014", "70000014", "2026-07-07"]
A20: Client Alpha (Steel EPC) | B20: CLIENT ALPHA STEEL STRUCTURE CORPORATION | C20: AR-00015 | D20: 70000015 | E20: 46218 | F20: 46293 | G20: 146356352 | H20: 0 | I20: 146356352 | J20: Senior Sales Rep 1 | K20: Trading | L20: Project 002 | M20: Collection note 009 | Q20: =IF(ISNUMBER(F20),Dashboard!$D$2-F20,"") -> 7 | R20: =IF(AND(OR(Dashboard!$P$1="All",A20=Dashboard!$P$1),OR(Dashboard!$P$2="All",J20=Dashboard!$P$2)),1,0) -> 1 | S20: =I20*R20 -> 146356352 | T20: =IF(AND(ISNUMBER(Q20),Q20>0),S20,0) -> 146356352 | U20: =IF(OR(Dashboard!$P$3="All",AND(Dashboard!$P$3="Not due",Q20<0),AND(Dashboard!$P$3="Due in 10 days",Q20>=-10,Q20<=0),AND(Dashboard!$P$3="Due in 30 days",Q20>=-30,Q20<=0),AND(Dashboard!$P$3="Overdue 1–60 days",Q20>0,Q20<=60),AND(Dashboard!$P$3="Over 60 days",Q20>60),AND(Dashboard!$P$3="All overdue",Q20>0)),1,0) -> 1 | V20: =S20*U20 -> 146356352 | W20: =IF(Q20>0,T20*Q20,0) -> 1024494464 | X20: =IF(V20>0,COUNTIF($V$6:V20,">0"),"") -> 15 | Y20: =C20&"|"&D20 -> AR-00015|70000015 | AA20: ["Demo Company 010", "AR-00015", "70000015", "2026-07-15"]
A21: Client Alpha (Steel EPC) | B21: CLIENT ALPHA STEEL STRUCTURE CORPORATION | C21: AR-00016 | D21: 70000016 | E21: 46220 | F21: 46295 | G21: 203352659 | H21: 0 | I21: 203352659 | J21: Senior Sales Rep 1 | K21: Trading | L21: Project 003 | M21: Collection note 008 | Q21: =IF(ISNUMBER(F21),Dashboard!$D$2-F21,"") -> 5 | R21: =IF(AND(OR(Dashboard!$P$1="All",A21=Dashboard!$P$1),OR(Dashboard!$P$2="All",J21=Dashboard!$P$2)),1,0) -> 1 | S21: =I21*R21 -> 203352659 | T21: =IF(AND(ISNUMBER(Q21),Q21>0),S21,0) -> 203352659 | U21: =IF(OR(Dashboard!$P$3="All",AND(Dashboard!$P$3="Not due",Q21<0),AND(Dashboard!$P$3="Due in 10 days",Q21>=-10,Q21<=0),AND(Dashboard!$P$3="Due in 30 days",Q21>=-30,Q21<=0),AND(Dashboard!$P$3="Overdue 1–60 days",Q21>0,Q21<=60),AND(Dashboard!$P$3="Over 60 days",Q21>60),AND(Dashboard!$P$3="All overdue",Q21>0)),1,0) -> 1 | V21: =S21*U21 -> 203352659 | W21: =IF(Q21>0,T21*Q21,0) -> 1016763295 | X21: =IF(V21>0,COUNTIF($V$6:V21,">0"),"") -> 16 | Y21: =C21&"|"&D21 -> AR-00016|70000016 | AA21: ["Demo Company 010", "AR-00016", "70000016", "2026-07-17"]
A22: Client Alpha (Steel EPC) | B22: CLIENT ALPHA STEEL STRUCTURE CORPORATION | C22: AR-00017 | D22: 70000017 | E22: 46220 | F22: 46295 | G22: 271688134 | H22: 0 | I22: 271688134 | J22: Senior Sales Rep 1 | K22: Trading | L22: Project 004 | M22: Collection note 008 | Q22: =IF(ISNUMBER(F22),Dashboard!$D$2-F22,"") -> 5 | R22: =IF(AND(OR(Dashboard!$P$1="All",A22=Dashboard!$P$1),OR(Dashboard!$P$2="All",J22=Dashboard!$P$2)),1,0) -> 1 | S22: =I22*R22 -> 271688134 | T22: =IF(AND(ISNUMBER(Q22),Q22>0),S22,0) -> 271688134 | U22: =IF(OR(Dashboard!$P$3="All",AND(Dashboard!$P$3="Not due",Q22<0),AND(Dashboard!$P$3="Due in 10 days",Q22>=-10,Q22<=0),AND(Dashboard!$P$3="Due in 30 days",Q22>=-30,Q22<=0),AND(Dashboard!$P$3="Overdue 1–60 days",Q22>0,Q22<=60),AND(Dashboard!$P$3="Over 60 days",Q22>60),AND(Dashboard!$P$3="All overdue",Q22>0)),1,0) -> 1 | V22: =S22*U22 -> 271688134 | W22: =IF(Q22>0,T22*Q22,0) -> 1358440670 | X22: =IF(V22>0,COUNTIF($V$6:V22,">0"),"") -> 17 | Y22: =C22&"|"&D22 -> AR-00017|70000017 | AA22: ["Demo Company 010", "AR-00017", "70000017", "2026-07-17"]
A23: Client Alpha (Steel EPC) | B23: CLIENT ALPHA STEEL STRUCTURE CORPORATION | C23: AR-00018 | D23: 70000018 | E23: 46220 | F23: 46295 | G23: 330520960 | H23: 0 | I23: 330520960 | J23: Senior Sales Rep 1 | K23: Trading | L23: Project 005 | M23: Collection note 008 | Q23: =IF(ISNUMBER(F23),Dashboard!$D$2-F23,"") -> 5 | R23: =IF(AND(OR(Dashboard!$P$1="All",A23=Dashboard!$P$1),OR(Dashboard!$P$2="All",J23=Dashboard!$P$2)),1,0) -> 1 | S23: =I23*R23 -> 330520960 | T23: =IF(AND(ISNUMBER(Q23),Q23>0),S23,0) -> 330520960 | U23: =IF(OR(Dashboard!$P$3="All",AND(Dashboard!$P$3="Not due",Q23<0),AND(Dashboard!$P$3="Due in 10 days",Q23>=-10,Q23<=0),AND(Dashboard!$P$3="Due in 30 days",Q23>=-30,Q23<=0),AND(Dashboard!$P$3="Overdue 1–60 days",Q23>0,Q23<=60),AND(Dashboard!$P$3="Over 60 days",Q23>60),AND(Dashboard!$P$3="All overdue",Q23>0)),1,0) -> 1 | V23: =S23*U23 -> 330520960 | W23: =IF(Q23>0,T23*Q23,0) -> 1652604800 | X23: =IF(V23>0,COUNTIF($V$6:V23,">0"),"") -> 18 | Y23: =C23&"|"&D23 -> AR-00018|70000018 | AA23: ["Demo Company 010", "AR-00018", "70000018", "2026-07-17"]
A24: Client Alpha (Steel EPC) | B24: CLIENT ALPHA STEEL STRUCTURE CORPORATION | C24: AR-00019 | D24: 70000019 | E24: 46225 | F24: 46300 | G24: 36887245 | H24: 0 | I24: 36887245 | J24: Senior Sales Rep 1 | K24: Trading | L24: Project 006 | M24: Collection note 007 | Q24: =IF(ISNUMBER(F24),Dashboard!$D$2-F24,"") -> 0 | R24: =IF(AND(OR(Dashboard!$P$1="All",A24=Dashboard!$P$1),OR(Dashboard!$P$2="All",J24=Dashboard!$P$2)),1,0) -> 1 | S24: =I24*R24 -> 36887245 | T24: =IF(AND(ISNUMBER(Q24),Q24>0),S24,0) -> 0 | U24: =IF(OR(Dashboard!$P$3="All",AND(Dashboard!$P$3="Not due",Q24<0),AND(Dashboard!$P$3="Due in 10 days",Q24>=-10,Q24<=0),AND(Dashboard!$P$3="Due in 30 days",Q24>=-30,Q24<=0),AND(Dashboard!$P$3="Overdue 1–60 days",Q24>0,Q24<=60),AND(Dashboard!$P$3="Over 60 days",Q24>60),AND(Dashboard!$P$3="All overdue",Q24>0)),1,0) -> 1 | V24: =S24*U24 -> 36887245 | W24: =IF(Q24>0,T24*Q24,0) -> 0 | X24: =IF(V24>0,COUNTIF($V$6:V24,">0"),"") -> 19 | Y24: =C24&"|"&D24 -> AR-00019|70000019 | AA24: ["Demo Company 010", "AR-00019", "70000019", "2026-07-22"]
... A70: Client Alpha (Steel EPC) | B70: CLIENT ALPHA STEEL STRUCTURE CORPORATION | C70: AR-00065 | D70: 70000065 | E70: 46282 | F70: 46357 | G70: 154151485 | H70: 0 | I70: 154151485 | J70: Senior Sales Rep 1 | K70: Trading | L70: Project 003 | M70: Collection note 011 | Q70: =IF(ISNUMBER(F70),Dashboard!$D$2-F70,"") -> -57 | R70: =IF(AND(OR(Dashboard!$P$1="All",A70=Dashboard!$P$1),OR(Dashboard!$P$2="All",J70=Dashboard!$P$2)),1,0) -> 1 | S70: =I70*R70 -> 154151485 | T70: =IF(AND(ISNUMBER(Q70),Q70>0),S70,0) -> 0 | U70: =IF(OR(Dashboard!$P$3="All",AND(Dashboard!$P$3="Not due",Q70<0),AND(Dashboard!$P$3="Due in 10 days",Q70>=-10,Q70<=0),AND(Dashboard!$P$3="Due in 30 days",Q70>=-30,Q70<=0),AND(Dashboard!$P$3="Overdue 1–60 days",Q70>0,Q70<=60),AND(Dashboard!$P$3="Over 60 days",Q70>60),AND(Dashboard!$P$3="All overdue",Q70>0)),1,0) -> 1 | V70: =S70*U70 -> 154151485 | W70: =IF(Q70>0,T70*Q70,0) -> 0 | X70: =IF(V70>0,COUNTIF($V$6:V70,">0"),"") -> 65 | Y70: =C70&"|"&D70 -> AR-00065|70000065 | AA70: ["Demo Company 010", "AR-00065", "70000065", "2026-09-17"]
A71: Client Alpha (Steel EPC) | B71: CLIENT ALPHA STEEL STRUCTURE CORPORATION | C71: AR-00066 | D71: 70000066 | E71: 46288 | F71: 46358 | G71: 1378039877 | H71: 0 | I71: 1378039877 | J71: Senior Sales Rep 2 | K71: Project | M71: Collection note 014 | Q71: =IF(ISNUMBER(F71),Dashboard!$D$2-F71,"") -> -58 | R71: =IF(AND(OR(Dashboard!$P$1="All",A71=Dashboard!$P$1),OR(Dashboard!$P$2="All",J71=Dashboard!$P$2)),1,0) -> 1 | S71: =I71*R71 -> 1378039877 | T71: =IF(AND(ISNUMBER(Q71),Q71>0),S71,0) -> 0 | U71: =IF(OR(Dashboard!$P$3="All",AND(Dashboard!$P$3="Not due",Q71<0),AND(Dashboard!$P$3="Due in 10 days",Q71>=-10,Q71<=0),AND(Dashboard!$P$3="Due in 30 days",Q71>=-30,Q71<=0),AND(Dashboard!$P$3="Overdue 1–60 days",Q71>0,Q71<=60),AND(Dashboard!$P$3="Over 60 days",Q71>60),AND(Dashboard!$P$3="All overdue",Q71>0)),1,0) -> 1 | V71: =S71*U71 -> 1378039877 | W71: =IF(Q71>0,T71*Q71,0) -> 0 | X71: =IF(V71>0,COUNTIF($V$6:V71,">0"),"") -> 66 | Y71: =C71&"|"&D71 -> AR-00066|70000066 | AA71: ["Demo Company 010", "AR-00066", "70000066", "2026-09-23"]
A72: Client Alpha (Steel EPC) | B72: CLIENT ALPHA STEEL STRUCTURE CORPORATION | C72: AR-00067 | D72: 70000067 | E72: 46288 | F72: 46358 | G72: 2781998738 | H72: 0 | I72: 2781998738 | J72: Senior Sales Rep 2 | K72: Project | M72: Collection note 015 | Q72: =IF(ISNUMBER(F72),Dashboard!$D$2-F72,"") -> -58 | R72: =IF(AND(OR(Dashboard!$P$1="All",A72=Dashboard!$P$1),OR(Dashboard!$P$2="All",J72=Dashboard!$P$2)),1,0) -> 1 | S72: =I72*R72 -> 2781998738 | T72: =IF(AND(ISNUMBER(Q72),Q72>0),S72,0) -> 0 | U72: =IF(OR(Dashboard!$P$3="All",AND(Dashboard!$P$3="Not due",Q72<0),AND(Dashboard!$P$3="Due in 10 days",Q72>=-10,Q72<=0),AND(Dashboard!$P$3="Due in 30 days",Q72>=-30,Q72<=0),AND(Dashboard!$P$3="Overdue 1–60 days",Q72>0,Q72<=60),AND(Dashboard!$P$3="Over 60 days",Q72>60),AND(Dashboard!$P$3="All overdue",Q72>0)),1,0) -> 1 | V72: =S72*U72 -> 2781998738 | W72: =IF(Q72>0,T72*Q72,0) -> 0 | X72: =IF(V72>0,COUNTIF($V$6:V72,">0"),"") -> 67 | Y72: =C72&"|"&D72 -> AR-00067|70000067 | AA72: ["Demo Company 010", "AR-00067", "70000067", "2026-09-23"]
A73: Client Alpha (Steel EPC) | B73: CLIENT ALPHA STEEL STRUCTURE CORPORATION | C73: AR-00068 | D73: 70000068 | E73: 46289 | F73: 46359 | G73: 1233595934 | H73: 0 | I73: 1233595934 | J73: Senior Sales Rep 2 | K73: Project | M73: Collection note 016 | Q73: =IF(ISNUMBER(F73),Dashboard!$D$2-F73,"") -> -59 | R73: =IF(AND(OR(Dashboard!$P$1="All",A73=Dashboard!$P$1),OR(Dashboard!$P$2="All",J73=Dashboard!$P$2)),1,0) -> 1 | S73: =I73*R73 -> 1233595934 | T73: =IF(AND(ISNUMBER(Q73),Q73>0),S73,0) -> 0 | U73: =IF(OR(Dashboard!$P$3="All",AND(Dashboard!$P$3="Not due",Q73<0),AND(Dashboard!$P$3="Due in 10 days",Q73>=-10,Q73<=0),AND(Dashboard!$P$3="Due in 30 days",Q73>=-30,Q73<=0),AND(Dashboard!$P$3="Overdue 1–60 days",Q73>0,Q73<=60),AND(Dashboard!$P$3="Over 60 days",Q73>60),AND(Dashboard!$P$3="All overdue",Q73>0)),1,0) -> 1 | V73: =S73*U73 -> 1233595934 | W73: =IF(Q73>0,T73*Q73,0) -> 0 | X73: =IF(V73>0,COUNTIF($V$6:V73,">0"),"") -> 68 | Y73: =C73&"|"&D73 -> AR-00068|70000068 | AA73: ["Demo Company 010", "AR-00068", "70000068", "2026-09-24"]
A74: Client Alpha (Steel EPC) | B74: CLIENT ALPHA STEEL STRUCTURE CORPORATION | C74: AR-00069 | D74: 70000069 | E74: 46289 | F74: 46359 | G74: 3074061247 | H74: 0 | I74: 3074061247 | J74: Senior Sales Rep 2 | K74: Project | M74: Collection note 017 | Q74: =IF(ISNUMBER(F74),Dashboard!$D$2-F74,"") -> -59 | R74: =IF(AND(OR(Dashboard!$P$1="All",A74=Dashboard!$P$1),OR(Dashboard!$P$2="All",J74=Dashboard!$P$2)),1,0) -> 1 | S74: =I74*R74 -> 3074061247 | T74: =IF(AND(ISNUMBER(Q74),Q74>0),S74,0) -> 0 | U74: =IF(OR(Dashboard!$P$3="All",AND(Dashboard!$P$3="Not due",Q74<0),AND(Dashboard!$P$3="Due in 10 days",Q74>=-10,Q74<=0),AND(Dashboard!$P$3="Due in 30 days",Q74>=-30,Q74<=0),AND(Dashboard!$P$3="Overdue 1–60 days",Q74>0,Q74<=60),AND(Dashboard!$P$3="Over 60 days",Q74>60),AND(Dashboard!$P$3="All overdue",Q74>0)),1,0) -> 1 | V74: =S74*U74 -> 3074061247 | W74: =IF(Q74>0,T74*Q74,0) -> 0 | X74: =IF(V74>0,COUNTIF($V$6:V74,">0"),"") -> 69 | Y74: =C74&"|"&D74 -> AR-00069|70000069 | AA74: ["Demo Company 010", "AR-00069", "70000069", "2026-09-24"]
A75: Client Alpha (Steel EPC) | B75: CLIENT ALPHA STEEL STRUCTURE CORPORATION | C75: AR-00070 | D75: 70000070 | E75: 46289 | F75: 46364 | G75: 349295 | H75: 0 | I75: 349295 | J75: Senior Sales Rep 1 | K75: Trading | L75: Project 008 | M75: Collection note 011 | Q75: =IF(ISNUMBER(F75),Dashboard!$D$2-F75,"") -> -64 | R75: =IF(AND(OR(Dashboard!$P$1="All",A75=Dashboard!$P$1),OR(Dashboard!$P$2="All",J75=Dashboard!$P$2)),1,0) -> 1 | S75: =I75*R75 -> 349295 | T75: =IF(AND(ISNUMBER(Q75),Q75>0),S75,0) -> 0 | U75: =IF(OR(Dashboard!$P$3="All",AND(Dashboard!$P$3="Not due",Q75<0),AND(Dashboard!$P$3="Due in 10 days",Q75>=-10,Q75<=0),AND(Dashboard!$P$3="Due in 30 days",Q75>=-30,Q75<=0),AND(Dashboard!$P$3="Overdue 1–60 days",Q75>0,Q75<=60),AND(Dashboard!$P$3="Over 60 days",Q75>60),AND(Dashboard!$P$3="All overdue",Q75>0)),1,0) -> 1 | V75: =S75*U75 -> 349295 | W75: =IF(Q75>0,T75*Q75,0) -> 0 | X75: =IF(V75>0,COUNTIF($V$6:V75,">0"),"") -> 70 | Y75: =C75&"|"&D75 -> AR-00070|70000070 | AA75: ["Demo Company 010", "AR-00070", "70000070", "2026-09-24"]
A76: Client Alpha (Steel EPC) | B76: CLIENT ALPHA STEEL STRUCTURE CORPORATION | C76: AR-00071 | D76: 70000071 | E76: 46289 | F76: 46364 | G76: 95221374 | H76: 0 | I76: 95221374 | J76: Senior Sales Rep 1 | K76: Trading | L76: Project 002 | M76: Collection note 011 | Q76: =IF(ISNUMBER(F76),Dashboard!$D$2-F76,"") -> -64 | R76: =IF(AND(OR(Dashboard!$P$1="All",A76=Dashboard!$P$1),OR(Dashboard!$P$2="All",J76=Dashboard!$P$2)),1,0) -> 1 | S76: =I76*R76 -> 95221374 | T76: =IF(AND(ISNUMBER(Q76),Q76>0),S76,0) -> 0 | U76: =IF(OR(Dashboard!$P$3="All",AND(Dashboard!$P$3="Not due",Q76<0),AND(Dashboard!$P$3="Due in 10 days",Q76>=-10,Q76<=0),AND(Dashboard!$P$3="Due in 30 days",Q76>=-30,Q76<=0),AND(Dashboard!$P$3="Overdue 1–60 days",Q76>0,Q76<=60),AND(Dashboard!$P$3="Over 60 days",Q76>60),AND(Dashboard!$P$3="All overdue",Q76>0)),1,0) -> 1 | V76: =S76*U76 -> 95221374 | W76: =IF(Q76>0,T76*Q76,0) -> 0 | X76: =IF(V76>0,COUNTIF($V$6:V76,">0"),"") -> 71 | Y76: =C76&"|"&D76 -> AR-00071|70000071 | AA76: ["Demo Company 010", "AR-00071", "70000071", "2026-09-24"]
A77: Client Alpha (Steel EPC) | B77: CLIENT ALPHA STEEL STRUCTURE CORPORATION | C77: AR-00072 | D77: 70000072 | E77: 46289 | F77: 46364 | G77: 9559012 | H77: 0 | I77: 9559012 | J77: Senior Sales Rep 1 | K77: Trading | L77: Project 003 | M77: Collection note 011 | Q77: =IF(ISNUMBER(F77),Dashboard!$D$2-F77,"") -> -64 | R77: =IF(AND(OR(Dashboard!$P$1="All",A77=Dashboard!$P$1),OR(Dashboard!$P$2="All",J77=Dashboard!$P$2)),1,0) -> 1 | S77: =I77*R77 -> 9559012 | T77: =IF(AND(ISNUMBER(Q77),Q77>0),S77,0) -> 0 | U77: =IF(OR(Dashboard!$P$3="All",AND(Dashboard!$P$3="Not due",Q77<0),AND(Dashboard!$P$3="Due in 10 days",Q77>=-10,Q77<=0),AND(Dashboard!$P$3="Due in 30 days",Q77>=-30,Q77<=0),AND(Dashboard!$P$3="Overdue 1–60 days",Q77>0,Q77<=60),AND(Dashboard!$P$3="Over 60 days",Q77>60),AND(Dashboard!$P$3="All overdue",Q77>0)),1,0) -> 1 | V77: =S77*U77 -> 9559012 | W77: =IF(Q77>0,T77*Q77,0) -> 0 | X77: =IF(V77>0,COUNTIF($V$6:V77,">0"),"") -> 72 | Y77: =C77&"|"&D77 -> AR-00072|70000072 | AA77: ["Demo Company 010", "AR-00072", "70000072", "2026-09-24"]
A78: Client Alpha (Steel EPC) | B78: CLIENT ALPHA STEEL STRUCTURE CORPORATION | C78: AR-00073 | D78: 70000073 | E78: 46289 | F78: 46364 | G78: 7011259 | H78: 0 | I78: 7011259 | J78: Senior Sales Rep 2 | K78: Trading | L78: Project 004 | M78: Collection note 013 | Q78: =IF(ISNUMBER(F78),Dashboard!$D$2-F78,"") -> -64 | R78: =IF(AND(OR(Dashboard!$P$1="All",A78=Dashboard!$P$1),OR(Dashboard!$P$2="All",J78=Dashboard!$P$2)),1,0) -> 1 | S78: =I78*R78 -> 7011259 | T78: =IF(AND(ISNUMBER(Q78),Q78>0),S78,0) -> 0 | U78: =IF(OR(Dashboard!$P$3="All",AND(Dashboard!$P$3="Not due",Q78<0),AND(Dashboard!$P$3="Due in 10 days",Q78>=-10,Q78<=0),AND(Dashboard!$P$3="Due in 30 days",Q78>=-30,Q78<=0),AND(Dashboard!$P$3="Overdue 1–60 days",Q78>0,Q78<=60),AND(Dashboard!$P$3="Over 60 days",Q78>60),AND(Dashboard!$P$3="All overdue",Q78>0)),1,0) -> 1 | V78: =S78*U78 -> 7011259 | W78: =IF(Q78>0,T78*Q78,0) -> 0 | X78: =IF(V78>0,COUNTIF($V$6:V78,">0"),"") -> 73 | Y78: =C78&"|"&D78 -> AR-00073|70000073 | AA78: ["Demo Company 010", "AR-00073", "70000073", "2026-09-24"]
A79: Client Alpha (Steel EPC) | B79: CLIENT ALPHA STEEL STRUCTURE CORPORATION | C79: AR-00074 | D79: 70000074 | E79: 46289 | F79: 46364 | G79: 5046104601 | H79: 0 | I79: 5046104601 | J79: Senior Sales Rep 2 | K79: Trading | L79: Project 005 | M79: Collection note 013 | Q79: =IF(ISNUMBER(F79),Dashboard!$D$2-F79,"") -> -64 | R79: =IF(AND(OR(Dashboard!$P$1="All",A79=Dashboard!$P$1),OR(Dashboard!$P$2="All",J79=Dashboard!$P$2)),1,0) -> 1 | S79: =I79*R79 -> 5046104601 | T79: =IF(AND(ISNUMBER(Q79),Q79>0),S79,0) -> 0 | U79: =IF(OR(Dashboard!$P$3="All",AND(Dashboard!$P$3="Not due",Q79<0),AND(Dashboard!$P$3="Due in 10 days",Q79>=-10,Q79<=0),AND(Dashboard!$P$3="Due in 30 days",Q79>=-30,Q79<=0),AND(Dashboard!$P$3="Overdue 1–60 days",Q79>0,Q79<=60),AND(Dashboard!$P$3="Over 60 days",Q79>60),AND(Dashboard!$P$3="All overdue",Q79>0)),1,0) -> 1 | V79: =S79*U79 -> 5046104601 | W79: =IF(Q79>0,T79*Q79,0) -> 0 | X79: =IF(V79>0,COUNTIF($V$6:V79,">0"),"") -> 74 | Y79: =C79&"|"&D79 -> AR-00074|70000074 | AA79: ["Demo Company 010", "AR-00074", "70000074", "2026-09-24"]
A80: Client Alpha (Steel EPC) | B80: CLIENT ALPHA STEEL STRUCTURE CORPORATION | C80: AR-00075 | D80: 70000075 | E80: 46289 | F80: 46364 | G80: 37392839 | H80: 0 | I80: 37392839 | J80: Senior Sales Rep 2 | K80: Trading | L80: Project 006 | M80: Collection note 013 | Q80: =IF(ISNUMBER(F80),Dashboard!$D$2-F80,"") -> -64 | R80: =IF(AND(OR(Dashboard!$P$1="All",A80=Dashboard!$P$1),OR(Dashboard!$P$2="All",J80=Dashboard!$P$2)),1,0) -> 1 | S80: =I80*R80 -> 37392839 | T80: =IF(AND(ISNUMBER(Q80),Q80>0),S80,0) -> 0 | U80: =IF(OR(Dashboard!$P$3="All",AND(Dashboard!$P$3="Not due",Q80<0),AND(Dashboard!$P$3="Due in 10 days",Q80>=-10,Q80<=0),AND(Dashboard!$P$3="Due in 30 days",Q80>=-30,Q80<=0),AND(Dashboard!$P$3="Overdue 1–60 days",Q80>0,Q80<=60),AND(Dashboard!$P$3="Over 60 days",Q80>60),AND(Dashboard!$P$3="All overdue",Q80>0)),1,0) -> 1 | V80: =S80*U80 -> 37392839 | W80: =IF(Q80>0,T80*Q80,0) -> 0 | X80: =IF(V80>0,COUNTIF($V$6:V80,">0"),"") -> 75 | Y80: =C80&"|"&D80 -> AR-00075|70000075 | AA80: ["Demo Company 010", "AR-00075", "70000075", "2026-09-24"]
A81: Client Alpha (Steel EPC) | B81: CLIENT ALPHA STEEL STRUCTURE CORPORATION | C81: AR-00076 | D81: 70000076 | E81: 46289 | F81: 46364 | G81: 2613764 | H81: 0 | I81: 2613764 | J81: Senior Sales Rep 2 | K81: Trading | L81: Project 007 | M81: Collection note 013 | Q81: =IF(ISNUMBER(F81),Dashboard!$D$2-F81,"") -> -64 | R81: =IF(AND(OR(Dashboard!$P$1="All",A81=Dashboard!$P$1),OR(Dashboard!$P$2="All",J81=Dashboard!$P$2)),1,0) -> 1 | S81: =I81*R81 -> 2613764 | T81: =IF(AND(ISNUMBER(Q81),Q81>0),S81,0) -> 0 | U81: =IF(OR(Dashboard!$P$3="All",AND(Dashboard!$P$3="Not due",Q81<0),AND(Dashboard!$P$3="Due in 10 days",Q81>=-10,Q81<=0),AND(Dashboard!$P$3="Due in 30 days",Q81>=-30,Q81<=0),AND(Dashboard!$P$3="Overdue 1–60 days",Q81>0,Q81<=60),AND(Dashboard!$P$3="Over 60 days",Q81>60),AND(Dashboard!$P$3="All overdue",Q81>0)),1,0) -> 1 | V81: =S81*U81 -> 2613764 | W81: =IF(Q81>0,T81*Q81,0) -> 0 | X81: =IF(V81>0,COUNTIF($V$6:V81,">0"),"") -> 76 | Y81: =C81&"|"&D81 -> AR-00076|70000076 | AA81: ["Demo Company 010", "AR-00076", "70000076", "2026-09-24"]
A82: Client Alpha (Steel EPC) | B82: CLIENT ALPHA STEEL STRUCTURE CORPORATION | C82: AR-00077 | D82: 70000077 | E82: 46294 | F82: 46369 | G82: 120506759 | H82: 0 | I82: 120506759 | J82: Senior Sales Rep 1 | K82: Trading | L82: Project 008 | M82: Collection note 006 | Q82: =IF(ISNUMBER(F82),Dashboard!$D$2-F82,"") -> -69 | R82: =IF(AND(OR(Dashboard!$P$1="All",A82=Dashboard!$P$1),OR(Dashboard!$P$2="All",J82=Dashboard!$P$2)),1,0) -> 1 | S82: =I82*R82 -> 120506759 | T82: =IF(AND(ISNUMBER(Q82),Q82>0),S82,0) -> 0 | U82: =IF(OR(Dashboard!$P$3="All",AND(Dashboard!$P$3="Not due",Q82<0),AND(Dashboard!$P$3="Due in 10 days",Q82>=-10,Q82<=0),AND(Dashboard!$P$3="Due in 30 days",Q82>=-30,Q82<=0),AND(Dashboard!$P$3="Overdue 1–60 days",Q82>0,Q82<=60),AND(Dashboard!$P$3="Over 60 days",Q82>60),AND(Dashboard!$P$3="All overdue",Q82>0)),1,0) -> 1 | V82: =S82*U82 -> 120506759 | W82: =IF(Q82>0,T82*Q82,0) -> 0 | X82: =IF(V82>0,COUNTIF($V$6:V82,">0"),"") -> 77 | Y82: =C82&"|"&D82 -> AR-00077|70000077 | AA82: ["Demo Company 010", "AR-00077", "70000077", "2026-09-29"]
A83: Client Alpha (Steel EPC) | B83: CLIENT ALPHA STEEL STRUCTURE CORPORATION | C83: AR-00078 | D83: 70000078 | E83: 46294 | F83: 46369 | G83: 120506759 | H83: 0 | I83: 120506759 | J83: Senior Sales Rep 1 | K83: Trading | L83: Project 002 | M83: Collection note 006 | Q83: =IF(ISNUMBER(F83),Dashboard!$D$2-F83,"") -> -69 | R83: =IF(AND(OR(Dashboard!$P$1="All",A83=Dashboard!$P$1),OR(Dashboard!$P$2="All",J83=Dashboard!$P$2)),1,0) -> 1 | S83: =I83*R83 -> 120506759 | T83: =IF(AND(ISNUMBER(Q83),Q83>0),S83,0) -> 0 | U83: =IF(OR(Dashboard!$P$3="All",AND(Dashboard!$P$3="Not due",Q83<0),AND(Dashboard!$P$3="Due in 10 days",Q83>=-10,Q83<=0),AND(Dashboard!$P$3="Due in 30 days",Q83>=-30,Q83<=0),AND(Dashboard!$P$3="Overdue 1–60 days",Q83>0,Q83<=60),AND(Dashboard!$P$3="Over 60 days",Q83>60),AND(Dashboard!$P$3="All overdue",Q83>0)),1,0) -> 1 | V83: =S83*U83 -> 120506759 | W83: =IF(Q83>0,T83*Q83,0) -> 0 | X83: =IF(V83>0,COUNTIF($V$6:V83,">0"),"") -> 78 | Y83: =C83&"|"&D83 -> AR-00078|70000078 | AA83: ["Demo Company 010", "AR-00078", "70000078", "2026-09-29"]
A84: Client Alpha (Steel EPC) | B84: CLIENT ALPHA STEEL STRUCTURE CORPORATION | C84: AR-00079 | D84: 70000079 | E84: 46294 | F84: 46369 | G84: 30367332 | H84: 0 | I84: 30367332 | J84: Senior Sales Rep 1 | K84: Trading | L84: Project 003 | M84: Collection note 009 | Q84: =IF(ISNUMBER(F84),Dashboard!$D$2-F84,"") -> -69 | R84: =IF(AND(OR(Dashboard!$P$1="All",A84=Dashboard!$P$1),OR(Dashboard!$P$2="All",J84=Dashboard!$P$2)),1,0) -> 1 | S84: =I84*R84 -> 30367332 | T84: =IF(AND(ISNUMBER(Q84),Q84>0),S84,0) -> 0 | U84: =IF(OR(Dashboard!$P$3="All",AND(Dashboard!$P$3="Not due",Q84<0),AND(Dashboard!$P$3="Due in 10 days",Q84>=-10,Q84<=0),AND(Dashboard!$P$3="Due in 30 days",Q84>=-30,Q84<=0),AND(Dashboard!$P$3="Overdue 1–60 days",Q84>0,Q84<=60),AND(Dashboard!$P$3="Over 60 days",Q84>60),AND(Dashboard!$P$3="All overdue",Q84>0)),1,0) -> 1 | V84: =S84*U84 -> 30367332 | W84: =IF(Q84>0,T84*Q84,0) -> 0 | X84: =IF(V84>0,COUNTIF($V$6:V84,">0"),"") -> 79 | Y84: =C84&"|"&D84 -> AR-00079|70000079 | AA84: ["Demo Company 010", "AR-00079", "70000079", "2026-09-29"]
A85: Client Alpha (Steel EPC) | B85: CLIENT ALPHA STEEL STRUCTURE CORPORATION | C85: AR-00080 | D85: 70000080 | E85: 46294 | F85: 46369 | G85: 1424478 | H85: 0 | I85: 1424478 | J85: Senior Sales Rep 1 | K85: Trading | L85: Project 004 | M85: Collection note 009 | Q85: =IF(ISNUMBER(F85),Dashboard!$D$2-F85,"") -> -69 | R85: =IF(AND(OR(Dashboard!$P$1="All",A85=Dashboard!$P$1),OR(Dashboard!$P$2="All",J85=Dashboard!$P$2)),1,0) -> 1 | S85: =I85*R85 -> 1424478 | T85: =IF(AND(ISNUMBER(Q85),Q85>0),S85,0) -> 0 | U85: =IF(OR(Dashboard!$P$3="All",AND(Dashboard!$P$3="Not due",Q85<0),AND(Dashboard!$P$3="Due in 10 days",Q85>=-10,Q85<=0),AND(Dashboard!$P$3="Due in 30 days",Q85>=-30,Q85<=0),AND(Dashboard!$P$3="Overdue 1–60 days",Q85>0,Q85<=60),AND(Dashboard!$P$3="Over 60 days",Q85>60),AND(Dashboard!$P$3="All overdue",Q85>0)),1,0) -> 1 | V85: =S85*U85 -> 1424478 | W85: =IF(Q85>0,T85*Q85,0) -> 0 | X85: =IF(V85>0,COUNTIF($V$6:V85,">0"),"") -> 80 | Y85: =C85&"|"&D85 -> AR-00080|70000080 | AA85: ["Demo Company 010", "AR-00080", "70000080", "2026-09-29"]
A86: Client Alpha (Steel EPC) | B86: CLIENT ALPHA STEEL STRUCTURE CORPORATION | C86: AR-00081 | D86: 70000081 | E86: 46294 | F86: 46369 | G86: 6760671 | H86: 0 | I86: 6760671 | J86: Senior Sales Rep 1 | K86: Trading | L86: Project 005 | M86: Collection note 009 | Q86: =IF(ISNUMBER(F86),Dashboard!$D$2-F86,"") -> -69 | R86: =IF(AND(OR(Dashboard!$P$1="All",A86=Dashboard!$P$1),OR(Dashboard!$P$2="All",J86=Dashboard!$P$2)),1,0) -> 1 | S86: =I86*R86 -> 6760671 | T86: =IF(AND(ISNUMBER(Q86),Q86>0),S86,0) -> 0 | U86: =IF(OR(Dashboard!$P$3="All",AND(Dashboard!$P$3="Not due",Q86<0),AND(Dashboard!$P$3="Due in 10 days",Q86>=-10,Q86<=0),AND(Dashboard!$P$3="Due in 30 days",Q86>=-30,Q86<=0),AND(Dashboard!$P$3="Overdue 1–60 days",Q86>0,Q86<=60),AND(Dashboard!$P$3="Over 60 days",Q86>60),AND(Dashboard!$P$3="All overdue",Q86>0)),1,0) -> 1 | V86: =S86*U86 -> 6760671 | W86: =IF(Q86>0,T86*Q86,0) -> 0 | X86: =IF(V86>0,COUNTIF($V$6:V86,">0"),"") -> 81 | Y86: =C86&"|"&D86 -> AR-00081|70000081 | AA86: ["Demo Company 010", "AR-00081", "70000081", "2026-09-29"]
... A101: Client Epsilon (Equipment) | B101: CLIENT EPSILON INDUSTRIAL EQUIPMENT LTD | C101: AR-00096 | D101: 70000096 | E101: 46294 | F101: 46324 | G101: 43462950 | H101: 0 | I101: 43462950 | J101: Sales Rep 4 | K101: Trading | L101: Project 006 | M101: Collection note 022 | Q101: =IF(ISNUMBER(F101),Dashboard!$D$2-F101,"") -> -24 | R101: =IF(AND(OR(Dashboard!$P$1="All",A101=Dashboard!$P$1),OR(Dashboard!$P$2="All",J101=Dashboard!$P$2)),1,0) -> 1 | S101: =I101*R101 -> 43462950 | T101: =IF(AND(ISNUMBER(Q101),Q101>0),S101,0) -> 0 | U101: =IF(OR(Dashboard!$P$3="All",AND(Dashboard!$P$3="Not due",Q101<0),AND(Dashboard!$P$3="Due in 10 days",Q101>=-10,Q101<=0),AND(Dashboard!$P$3="Due in 30 days",Q101>=-30,Q101<=0),AND(Dashboard!$P$3="Overdue 1–60 days",Q101>0,Q101<=60),AND(Dashboard!$P$3="Over 60 days",Q101>60),AND(Dashboard!$P$3="All overdue",Q101>0)),1,0) -> 1 | V101: =S101*U101 -> 43462950 | W101: =IF(Q101>0,T101*Q101,0) -> 0 | X101: =IF(V101>0,COUNTIF($V$6:V101,">0"),"") -> 96 | Y101: =C101&"|"&D101 -> AR-00096|70000096 | AA101: ["CLIENT EPSILON DEMO COMPANY", "AR-00096", "70000096", "2026-09-29"]
...

Sheet Prior AR
A1: Prior-period invoice ledger used for comparison. Public demonstration data.
D3: 46284
A5: Customer | B5: Legal Name | C5: Document Number | D5: Invoice Number | E5: Invoice Date | F5: Due Date | G5: Invoice Gross Amount | H5: Receipts Applied | I5: Outstanding Balance | J5: Sales Representative | K5: Business Type | L5: Project | M5: Description | N5: Promised Payment Date | O5: Last Contact | P5: Next Action | Q5: Days Overdue | R5: Customer / Staff Match | S5: Selected Balance | T5: Selected Overdue | U5: Status Match | V5: Filtered Balance | W5: Overdue Days × Balance
A6: Client Beta (Heavy Const.) | B6: CLIENT BETA HEAVY INDUSTRIAL CONSTRUCTION CORP | C6: AR-00001 | D6: 70000001 | E6: 46262 | F6: 46292 | G6: 78091274 | H6: 0 | I6: 78091274 | J6: Senior Sales Rep 1 | K6: Trading | L6: Project 009 | M6: Collection note 001 | Q6: =IF(ISNUMBER(F6),$D$3-F6,"") -> -8 | R6: =IF(AND(OR(Dashboard!$P$1="All",A6=Dashboard!$P$1),OR(Dashboard!$P$2="All",J6=Dashboard!$P$2)),1,0) -> 1 | S6: =I6*R6 -> 78091274 | T6: =IF(AND(ISNUMBER(Q6),Q6>0),S6,0) -> 0 | U6: =IF(OR(Dashboard!$P$3="All",AND(Dashboard!$P$3="Not due",Q6<0),AND(Dashboard!$P$3="Due in 10 days",Q6>=-10,Q6<=0),AND(Dashboard!$P$3="Due in 30 days",Q6>=-30,Q6<=0),AND(Dashboard!$P$3="Overdue 1–60 days",Q6>0,Q6<=60),AND(Dashboard!$P$3="Over 60 days",Q6>60),AND(Dashboard!$P$3="All overdue",Q6>0)),1,0) -> 1 | V6: =S6*U6 -> 78091274 | W6: =IF(Q6>0,T6*Q6,0) -> 0 | X6: =IF(V6>0,COUNTIF($V$6:V6,">0"),"") -> 1 | Y6: =C6&"|"&D6 -> AR-00001|70000001
A7: Client Beta (Heavy Const.) | B7: CLIENT BETA HEAVY INDUSTRIAL CONSTRUCTION CORP | C7: AR-00002 | D7: 70000002 | E7: 46262 | F7: 46292 | G7: 952138129 | H7: 0 | I7: 952138129 | J7: Senior Sales Rep 1 | K7: Trading | L7: Project 009 | M7: Collection note 001 | Q7: =IF(ISNUMBER(F7),$D$3-F7,"") -> -8 | R7: =IF(AND(OR(Dashboard!$P$1="All",A7=Dashboard!$P$1),OR(Dashboard!$P$2="All",J7=Dashboard!$P$2)),1,0) -> 1 | S7: =I7*R7 -> 952138129 | T7: =IF(AND(ISNUMBER(Q7),Q7>0),S7,0) -> 0 | U7: =IF(OR(Dashboard!$P$3="All",AND(Dashboard!$P$3="Not due",Q7<0),AND(Dashboard!$P$3="Due in 10 days",Q7>=-10,Q7<=0),AND(Dashboard!$P$3="Due in 30 days",Q7>=-30,Q7<=0),AND(Dashboard!$P$3="Overdue 1–60 days",Q7>0,Q7<=60),AND(Dashboard!$P$3="Over 60 days",Q7>60),AND(Dashboard!$P$3="All overdue",Q7>0)),1,0) -> 1 | V7: =S7*U7 -> 952138129 | W7: =IF(Q7>0,T7*Q7,0) -> 0 | X7: =IF(V7>0,COUNTIF($V$6:V7,">0"),"") -> 2 | Y7: =C7&"|"&D7 -> AR-00002|70000002
A8: Client Beta (Heavy Const.) | B8: CLIENT BETA HEAVY INDUSTRIAL CONSTRUCTION CORP | C8: AR-00003 | D8: 70000003 | E8: 46262 | F8: 46292 | G8: 572943345 | H8: 0 | I8: 572943345 | J8: Senior Sales Rep 1 | K8: Trading | L8: Project 009 | M8: Collection note 001 | Q8: =IF(ISNUMBER(F8),$D$3-F8,"") -> -8 | R8: =IF(AND(OR(Dashboard!$P$1="All",A8=Dashboard!$P$1),OR(Dashboard!$P$2="All",J8=Dashboard!$P$2)),1,0) -> 1 | S8: =I8*R8 -> 572943345 | T8: =IF(AND(ISNUMBER(Q8),Q8>0),S8,0) -> 0 | U8: =IF(OR(Dashboard!$P$3="All",AND(Dashboard!$P$3="Not due",Q8<0),AND(Dashboard!$P$3="Due in 10 days",Q8>=-10,Q8<=0),AND(Dashboard!$P$3="Due in 30 days",Q8>=-30,Q8<=0),AND(Dashboard!$P$3="Overdue 1–60 days",Q8>0,Q8<=60),AND(Dashboard!$P$3="Over 60 days",Q8>60),AND(Dashboard!$P$3="All overdue",Q8>0)),1,0) -> 1 | V8: =S8*U8 -> 572943345 | W8: =IF(Q8>0,T8*Q8,0) -> 0 | X8: =IF(V8>0,COUNTIF($V$6:V8,">0"),"") -> 3 | Y8: =C8&"|"&D8 -> AR-00003|70000003
A9: Client Alpha (Steel EPC) | B9: CLIENT ALPHA STEEL STRUCTURE CORPORATION | C9: AR-00099 | D9: 70000099 | E9: 46161 | F9: 46236 | G9: 673993453 | H9: 0 | I9: 673993453 | J9: Senior Sales Rep 2 | K9: Trading | L9: Project 010 | M9: Collection note 013 | Q9: =IF(ISNUMBER(F9),$D$3-F9,"") -> 48 | R9: =IF(AND(OR(Dashboard!$P$1="All",A9=Dashboard!$P$1),OR(Dashboard!$P$2="All",J9=Dashboard!$P$2)),1,0) -> 1 | S9: =I9*R9 -> 673993453 | T9: =IF(AND(ISNUMBER(Q9),Q9>0),S9,0) -> 673993453 | U9: =IF(OR(Dashboard!$P$3="All",AND(Dashboard!$P$3="Not due",Q9<0),AND(Dashboard!$P$3="Due in 10 days",Q9>=-10,Q9<=0),AND(Dashboard!$P$3="Due in 30 days",Q9>=-30,Q9<=0),AND(Dashboard!$P$3="Overdue 1–60 days",Q9>0,Q9<=60),AND(Dashboard!$P$3="Over 60 days",Q9>60),AND(Dashboard!$P$3="All overdue",Q9>0)),1,0) -> 1 | V9: =S9*U9 -> 673993453 | W9: =IF(Q9>0,T9*Q9,0) -> 32351685744 | X9: =IF(V9>0,COUNTIF($V$6:V9,">0"),"") -> 4 | Y9: =C9&"|"&D9 -> AR-00099|70000099
A10: Client Alpha (Steel EPC) | B10: CLIENT ALPHA STEEL STRUCTURE CORPORATION | C10: AR-00100 | D10: 70000100 | E10: 46167 | F10: 46242 | G10: 554101470 | H10: 451313869 | I10: 102787601 | J10: Senior Sales Rep 1 | K10: Trading | L10: Project 011 | M10: Collection note 006 | Q10: =IF(ISNUMBER(F10),$D$3-F10,"") -> 42 | R10: =IF(AND(OR(Dashboard!$P$1="All",A10=Dashboard!$P$1),OR(Dashboard!$P$2="All",J10=Dashboard!$P$2)),1,0) -> 1 | S10: =I10*R10 -> 102787601 | T10: =IF(AND(ISNUMBER(Q10),Q10>0),S10,0) -> 102787601 | U10: =IF(OR(Dashboard!$P$3="All",AND(Dashboard!$P$3="Not due",Q10<0),AND(Dashboard!$P$3="Due in 10 days",Q10>=-10,Q10<=0),AND(Dashboard!$P$3="Due in 30 days",Q10>=-30,Q10<=0),AND(Dashboard!$P$3="Overdue 1–60 days",Q10>0,Q10<=60),AND(Dashboard!$P$3="Over 60 days",Q10>60),AND(Dashboard!$P$3="All overdue",Q10>0)),1,0) -> 1 | V10: =S10*U10 -> 102787601 | W10: =IF(Q10>0,T10*Q10,0) -> 4317079242 | X10: =IF(V10>0,COUNTIF($V$6:V10,">0"),"") -> 5 | Y10: =C10&"|"&D10 -> AR-00100|70000100
A11: Client Alpha (Steel EPC) | B11: CLIENT ALPHA STEEL STRUCTURE CORPORATION | C11: AR-00101 | D11: 70000101 | E11: 46167 | F11: 46242 | G11: 34830763 | H11: 0 | I11: 34830763 | J11: Senior Sales Rep 1 | K11: Trading | L11: Project 011 | M11: Collection note 006 | Q11: =IF(ISNUMBER(F11),$D$3-F11,"") -> 42 | R11: =IF(AND(OR(Dashboard!$P$1="All",A11=Dashboard!$P$1),OR(Dashboard!$P$2="All",J11=Dashboard!$P$2)),1,0) -> 1 | S11: =I11*R11 -> 34830763 | T11: =IF(AND(ISNUMBER(Q11),Q11>0),S11,0) -> 34830763 | U11: =IF(OR(Dashboard!$P$3="All",AND(Dashboard!$P$3="Not due",Q11<0),AND(Dashboard!$P$3="Due in 10 days",Q11>=-10,Q11<=0),AND(Dashboard!$P$3="Due in 30 days",Q11>=-30,Q11<=0),AND(Dashboard!$P$3="Overdue 1–60 days",Q11>0,Q11<=60),AND(Dashboard!$P$3="Over 60 days",Q11>60),AND(Dashboard!$P$3="All overdue",Q11>0)),1,0) -> 1 | V11: =S11*U11 -> 34830763 | W11: =IF(Q11>0,T11*Q11,0) -> 1462892046 | X11: =IF(V11>0,COUNTIF($V$6:V11,">0"),"") -> 6 | Y11: =C11&"|"&D11 -> AR-00101|70000101
A12: Client Alpha (Steel EPC) | B12: CLIENT ALPHA STEEL STRUCTURE CORPORATION | C12: AR-00102 | D12: 70000102 | E12: 46167 | F12: 46242 | G12: 207794714 | H12: 0 | I12: 207794714 | J12: Senior Sales Rep 1 | K12: Trading | L12: Project 011 | M12: Collection note 006 | Q12: =IF(ISNUMBER(F12),$D$3-F12,"") -> 42 | R12: =IF(AND(OR(Dashboard!$P$1="All",A12=Dashboard!$P$1),OR(Dashboard!$P$2="All",J12=Dashboard!$P$2)),1,0) -> 1 | S12: =I12*R12 -> 207794714 | T12: =IF(AND(ISNUMBER(Q12),Q12>0),S12,0) -> 207794714 | U12: =IF(OR(Dashboard!$P$3="All",AND(Dashboard!$P$3="Not due",Q12<0),AND(Dashboard!$P$3="Due in 10 days",Q12>=-10,Q12<=0),AND(Dashboard!$P$3="Due in 30 days",Q12>=-30,Q12<=0),AND(Dashboard!$P$3="Overdue 1–60 days",Q12>0,Q12<=60),AND(Dashboard!$P$3="Over 60 days",Q12>60),AND(Dashboard!$P$3="All overdue",Q12>0)),1,0) -> 1 | V12: =S12*U12 -> 207794714 | W12: =IF(Q12>0,T12*Q12,0) -> 8727377988 | X12: =IF(V12>0,COUNTIF($V$6:V12,">0"),"") -> 7 | Y12: =C12&"|"&D12 -> AR-00102|70000102
A13: Client Alpha (Steel EPC) | B13: CLIENT ALPHA STEEL STRUCTURE CORPORATION | C13: AR-00103 | D13: 70000103 | E13: 46167 | F13: 46242 | G13: 505495089 | H13: 0 | I13: 505495089 | J13: Senior Sales Rep 2 | K13: Trading | L13: Project 010 | M13: Collection note 013 | Q13: =IF(ISNUMBER(F13),$D$3-F13,"") -> 42 | R13: =IF(AND(OR(Dashboard!$P$1="All",A13=Dashboard!$P$1),OR(Dashboard!$P$2="All",J13=Dashboard!$P$2)),1,0) -> 1 | S13: =I13*R13 -> 505495089 | T13: =IF(AND(ISNUMBER(Q13),Q13>0),S13,0) -> 505495089 | U13: =IF(OR(Dashboard!$P$3="All",AND(Dashboard!$P$3="Not due",Q13<0),AND(Dashboard!$P$3="Due in 10 days",Q13>=-10,Q13<=0),AND(Dashboard!$P$3="Due in 30 days",Q13>=-30,Q13<=0),AND(Dashboard!$P$3="Overdue 1–60 days",Q13>0,Q13<=60),AND(Dashboard!$P$3="Over 60 days",Q13>60),AND(Dashboard!$P$3="All overdue",Q13>0)),1,0) -> 1 | V13: =S13*U13 -> 505495089 | W13: =IF(Q13>0,T13*Q13,0) -> 21230793738 | X13: =IF(V13>0,COUNTIF($V$6:V13,">0"),"") -> 8 | Y13: =C13&"|"&D13 -> AR-00103|70000103
A14: Client Alpha (Steel EPC) | B14: CLIENT ALPHA STEEL STRUCTURE CORPORATION | C14: AR-00104 | D14: 70000104 | E14: 46171 | F14: 46246 | G14: 130289125 | H14: 0 | I14: 130289125 | J14: Senior Sales Rep 1 | K14: Trading | L14: Project 011 | M14: Collection note 006 | Q14: =IF(ISNUMBER(F14),$D$3-F14,"") -> 38 | R14: =IF(AND(OR(Dashboard!$P$1="All",A14=Dashboard!$P$1),OR(Dashboard!$P$2="All",J14=Dashboard!$P$2)),1,0) -> 1 | S14: =I14*R14 -> 130289125 | T14: =IF(AND(ISNUMBER(Q14),Q14>0),S14,0) -> 130289125 | U14: =IF(OR(Dashboard!$P$3="All",AND(Dashboard!$P$3="Not due",Q14<0),AND(Dashboard!$P$3="Due in 10 days",Q14>=-10,Q14<=0),AND(Dashboard!$P$3="Due in 30 days",Q14>=-30,Q14<=0),AND(Dashboard!$P$3="Overdue 1–60 days",Q14>0,Q14<=60),AND(Dashboard!$P$3="Over 60 days",Q14>60),AND(Dashboard!$P$3="All overdue",Q14>0)),1,0) -> 1 | V14: =S14*U14 -> 130289125 | W14: =IF(Q14>0,T14*Q14,0) -> 4950986750 | X14: =IF(V14>0,COUNTIF($V$6:V14,">0"),"") -> 9 | Y14: =C14&"|"&D14 -> AR-00104|70000104
A15: Client Alpha (Steel EPC) | B15: CLIENT ALPHA STEEL STRUCTURE CORPORATION | C15: AR-00105 | D15: 70000105 | E15: 46184 | F15: 46259 | G15: 505495089 | H15: 0 | I15: 505495089 | J15: Senior Sales Rep 2 | K15: Trading | L15: Project 010 | M15: Collection note 013 | Q15: =IF(ISNUMBER(F15),$D$3-F15,"") -> 25 | R15: =IF(AND(OR(Dashboard!$P$1="All",A15=Dashboard!$P$1),OR(Dashboard!$P$2="All",J15=Dashboard!$P$2)),1,0) -> 1 | S15: =I15*R15 -> 505495089 | T15: =IF(AND(ISNUMBER(Q15),Q15>0),S15,0) -> 505495089 | U15: =IF(OR(Dashboard!$P$3="All",AND(Dashboard!$P$3="Not due",Q15<0),AND(Dashboard!$P$3="Due in 10 days",Q15>=-10,Q15<=0),AND(Dashboard!$P$3="Due in 30 days",Q15>=-30,Q15<=0),AND(Dashboard!$P$3="Overdue 1–60 days",Q15>0,Q15<=60),AND(Dashboard!$P$3="Over 60 days",Q15>60),AND(Dashboard!$P$3="All overdue",Q15>0)),1,0) -> 1 | V15: =S15*U15 -> 505495089 | W15: =IF(Q15>0,T15*Q15,0) -> 12637377225 | X15: =IF(V15>0,COUNTIF($V$6:V15,">0"),"") -> 10 | Y15: =C15&"|"&D15 -> AR-00105|70000105
A16: Client Alpha (Steel EPC) | B16: CLIENT ALPHA STEEL STRUCTURE CORPORATION | C16: AR-00009 | D16: 70000009 | E16: 46189 | F16: 46264 | G16: 97367488 | H16: 0 | I16: 97367488 | J16: Senior Sales Rep 1 | K16: Trading | L16: Project 012 | M16: Collection note 005 | Q16: =IF(ISNUMBER(F16),$D$3-F16,"") -> 20 | R16: =IF(AND(OR(Dashboard!$P$1="All",A16=Dashboard!$P$1),OR(Dashboard!$P$2="All",J16=Dashboard!$P$2)),1,0) -> 1 | S16: =I16*R16 -> 97367488 | T16: =IF(AND(ISNUMBER(Q16),Q16>0),S16,0) -> 97367488 | U16: =IF(OR(Dashboard!$P$3="All",AND(Dashboard!$P$3="Not due",Q16<0),AND(Dashboard!$P$3="Due in 10 days",Q16>=-10,Q16<=0),AND(Dashboard!$P$3="Due in 30 days",Q16>=-30,Q16<=0),AND(Dashboard!$P$3="Overdue 1–60 days",Q16>0,Q16<=60),AND(Dashboard!$P$3="Over 60 days",Q16>60),AND(Dashboard!$P$3="All overdue",Q16>0)),1,0) -> 1 | V16: =S16*U16 -> 97367488 | W16: =IF(Q16>0,T16*Q16,0) -> 1947349760 | X16: =IF(V16>0,COUNTIF($V$6:V16,">0"),"") -> 11 | Y16: =C16&"|"&D16 -> AR-00009|70000009
A17: Client Alpha (Steel EPC) | B17: CLIENT ALPHA STEEL STRUCTURE CORPORATION | C17: AR-00010 | D17: 70000010 | E17: 46191 | F17: 46266 | G17: 483414781 | H17: 0 | I17: 483414781 | J17: Senior Sales Rep 1 | K17: Trading | L17: Project 011 | M17: Collection note 006 | Q17: =IF(ISNUMBER(F17),$D$3-F17,"") -> 18 | R17: =IF(AND(OR(Dashboard!$P$1="All",A17=Dashboard!$P$1),OR(Dashboard!$P$2="All",J17=Dashboard!$P$2)),1,0) -> 1 | S17: =I17*R17 -> 483414781 | T17: =IF(AND(ISNUMBER(Q17),Q17>0),S17,0) -> 483414781 | U17: =IF(OR(Dashboard!$P$3="All",AND(Dashboard!$P$3="Not due",Q17<0),AND(Dashboard!$P$3="Due in 10 days",Q17>=-10,Q17<=0),AND(Dashboard!$P$3="Due in 30 days",Q17>=-30,Q17<=0),AND(Dashboard!$P$3="Overdue 1–60 days",Q17>0,Q17<=60),AND(Dashboard!$P$3="Over 60 days",Q17>60),AND(Dashboard!$P$3="All overdue",Q17>0)),1,0) -> 1 | V17: =S17*U17 -> 483414781 | W17: =IF(Q17>0,T17*Q17,0) -> 8701466058 | X17: =IF(V17>0,COUNTIF($V$6:V17,">0"),"") -> 12 | Y17: =C17&"|"&D17 -> AR-00010|70000010
... A84: Client Gamma (Offshore Energy) | B84: Demo Company 399 | C84: AR-00098 | D84: 70000098 | E84: 46172 | F84: 46217 | G84: 4099303796 | H84: 0 | I84: 4099303796 | J84: Sales Rep 3 | K84: Trading | L84: Project 017 | M84: Collection note 024 | Q84: =IF(ISNUMBER(F84),$D$3-F84,"") -> 67 | R84: =IF(AND(OR(Dashboard!$P$1="All",A84=Dashboard!$P$1),OR(Dashboard!$P$2="All",J84=Dashboard!$P$2)),1,0) -> 1 | S84: =I84*R84 -> 4099303796 | T84: =IF(AND(ISNUMBER(Q84),Q84>0),S84,0) -> 4099303796 | U84: =IF(OR(Dashboard!$P$3="All",AND(Dashboard!$P$3="Not due",Q84<0),AND(Dashboard!$P$3="Due in 10 days",Q84>=-10,Q84<=0),AND(Dashboard!$P$3="Due in 30 days",Q84>=-30,Q84<=0),AND(Dashboard!$P$3="Overdue 1–60 days",Q84>0,Q84<=60),AND(Dashboard!$P$3="Over 60 days",Q84>60),AND(Dashboard!$P$3="All overdue",Q84>0)),1,0) -> 1 | V84: =S84*U84 -> 4099303796 | W84: =IF(Q84>0,T84*Q84,0) -> 274653354332 | X84: =IF(V84>0,COUNTIF($V$6:V84,">0"),"") -> 79 | Y84: =C84&"|"&D84 -> AR-00098|70000098
