Workbook
Name AR_Customers: Analysis!$V$170:$V$177
Name AR_Sales: Analysis!$W$170:$W$176

Sheet Dashboard
B1: ACCOUNTS RECEIVABLE DASHBOARD | N1: Client Filter | P1: All | AA1: =IF(Analysis!D7=0,AD1,"") | AB1: =IF(Analysis!D7>0,AD1,"") | AC1: =IF(Analysis!D7<0,AD1,"") -> -0.05B (-0.8%) | AD1: =TEXT(Analysis!D7/1000000000,"+0.00;-0.00;0.00")&"B ("&TEXT(Analysis!E7,"+0.0%;-0.0%;0.0%")&")" -> -0.05B (-0.8%) | AE1: ="Current: "&TEXT(Analysis!B7/1000000000,"0.00")&"B VND" -> Current: 5.78B VND | AF1: ="Prior: "&TEXT(Analysis!C7/1000000000,"0.00")&"B VND" -> Prior: 5.83B VND | AG1: Overdue Ratio (1–60 Days) | AH1: =TEXT(Analysis!B16,"0.0%") -> 11.3%
B2: Report Date: | D2: 45777 | N2: Sales Rep Filter | P2: All | AA2: =IF(Analysis!D8=0,AD2,"") | AB2: =IF(Analysis!D8>0,AD2,"") | AC2: =IF(Analysis!D8<0,AD2,"") -> -0.08B (-1.9%) | AD2: =TEXT(Analysis!D8/1000000000,"+0.00;-0.00;0.00")&"B ("&TEXT(Analysis!E8,"+0.0%;-0.0%;0.0%")&")" -> -0.08B (-1.9%) | AE2: ="Current: "&TEXT(Analysis!B8/1000000000,"0.00")&"B VND" -> Current: 4.02B VND | AF2: ="Prior: "&TEXT(Analysis!C8/1000000000,"0.00")&"B VND" -> Prior: 4.10B VND | AG2: Receivables Ratio (>60 Days) | AH2: =TEXT(Analysis!B17,"0.0%") -> 7.9%
B3: Fictional details; retained aggregate presentation | Illustrative 20% threshold | N3: Status Filter | P3: All | AA3: =IF(Analysis!D9=0,AD3,"") | AB3: =IF(Analysis!D9>0,AD3,"") | AC3: =IF(Analysis!D9<0,AD3,"") -> -0.13B (-1.3%) | AD3: =TEXT(Analysis!D9/1000000000,"+0.00;-0.00;0.00")&"B ("&TEXT(Analysis!E9,"+0.0%;-0.0%;0.0%")&")" -> -0.13B (-1.3%) | AE3: ="Current: "&TEXT(Analysis!B9/1000000000,"0.00")&"B VND" -> Current: 9.80B VND | AF3: ="Prior: "&TEXT(Analysis!C9/1000000000,"0.00")&"B VND" -> Prior: 9.93B VND | AG3: Total Overdue Ratio | AH3: =TEXT(Analysis!B18,"0.0%") -> 19.2%
B6: Total Outstanding AR | E6: Avg Overdue Days | G6: >60d / Total Overdue | I6: Top Client Share | K6: Top 3 Clients Share | N6: Due in Next 10 Days | Z6: =Analysis!D6 -> 17123355003
B7: =TEXT(Analysis!B6/1000000000,"0.00")&"B VND" -> 51.06B VND | E7: =TEXT(Analysis!B56,"0.0")&" Days" -> 39.5 Days | G7: =TEXT(Analysis!B57,"0.0%") -> 41.0% | I7: =TEXT(Analysis!B58,"0.0%") -> 76.5% | K7: =TEXT(Analysis!B59,"0.0%") -> 91.5% | N7: =TEXT(Analysis!B11/1000000000,"0.00")&"B VND" -> 3.81B VND
B9: ="Prior: "&TEXT(Analysis!C6/1000000000,"0.00")&"B VND" -> Prior: 33.93B VND | E9: ="Prior: "&TEXT(Analysis!C56,"0.0")&" Days" -> Prior: 40.0 Days | G9: ="Prior: "&TEXT(Analysis!C57,"0.0%") -> Prior: 41.3% | I9: ="Prior: "&TEXT(Analysis!C58,"0.0%") -> Prior: 69.9% | K9: ="Prior: "&TEXT(Analysis!C59,"0.0%") -> Prior: 95.3% | N9: ="Prior: "&TEXT(Analysis!C11/1000000000,"0.00")&"B VND" -> Prior: 3.35B VND
B10: =TEXT(Analysis!D6/1000000000,"+0.00;-0.00;0.00")&"B ("&TEXT(Analysis!E6,"+0.0%;-0.0%;0.0%")&")" -> +17.12B (+50.5%) | E10: =TEXT(Analysis!D56,"+0.0;-0.0;0.0")&" Days ("&TEXT(Analysis!E56,"+0.0%;-0.0%;0.0%")&")" -> -0.5 Days (-1.3%) | G10: =TEXT(Analysis!D57*100,"+0.0;-0.0;0.0")&" pp" -> -0.3 pp | I10: =TEXT(Analysis!D58*100,"+0.0;-0.0;0.0")&" pp" -> +6.6 pp | K10: =TEXT(Analysis!D59*100,"+0.0;-0.0;0.0")&" pp" -> -3.7 pp | N10: =TEXT(Analysis!D11/1000000000,"+0.00;-0.00;0.00")&"B ("&TEXT(Analysis!E11,"+0.0%;-0.0%;0.0%")&")" -> +0.47B (+13.9%)
Z11: =Analysis!D11 -> 4.6513087e+08
B12: Overdue Ratio (1–60 Days) | G12: Receivables Ratio (>60 Days) | K12: Total Overdue Ratio
B21: =TEXT(Analysis!B16,"0.0%") -> 11.3% | G21: =TEXT(Analysis!B17,"0.0%") -> 7.9% | K21: =TEXT(Analysis!B18,"0.0%") -> 19.2%
B22: ="Current: "&TEXT(Analysis!B7/1000000000,"0.00")&" B VND" -> Current: 5.78 B VND | G22: ="Current: "&TEXT(Analysis!B8/1000000000,"0.00")&" B VND" -> Current: 4.02 B VND | K22: ="Current: "&TEXT(Analysis!B9/1000000000,"0.00")&" B VND" -> Current: 9.80 B VND
B27: Customer/staff filters apply to the overview. Status also filters the charts and collection list.
B28: 98 current invoices. All customer and staff groups reconcile to the current ledger total.
Z56: =Analysis!D56 -> -0.52699736
Z57: =Analysis!D57 -> -0.0026233795
Z58: =Analysis!D58 -> 0.065755063
Z59: =Analysis!D59 -> -0.037499327
B69: Client Account | D69: Current Balance | F69: Prior Balance | G69: In-Term Debt | H69: Overdue Debt | J69: Sales Representative | K69: Current Balance | L69: Prior Balance | N69: In-Term Debt | P69: Overdue Debt
B70: Customer 01 | D70: =Analysis!B170 -> 2000343001 | F70: =Analysis!C170 -> 1603172748 | G70: =Analysis!D170 -> 450339000 | H70: =Analysis!E170 -> 1550004001 | J70: Staff 01 | K70: =Analysis!H170 -> 14614668379 | L70: =Analysis!I170 -> 1.4415883e+10 | N70: =Analysis!J170 -> 10509252379 | P70: =Analysis!K170 -> 4105416000
B71: Customer 02 | D71: =Analysis!B171 -> 2283113999 | F71: =Analysis!C171 -> 0 | G71: =Analysis!D171 -> 2283113999 | H71: =Analysis!E171 -> 0 | J71: Staff 02 | K71: =Analysis!H171 -> 3.0092673e+10 | L71: =Analysis!I171 -> 1.5416999e+10 | N71: =Analysis!J171 -> 2.8416993e+10 | P71: =Analysis!K171 -> 1675680000
B72: Customer 03 | D72: =Analysis!B172 -> 39053817000 | F72: =Analysis!C172 -> 2.3724533e+10 | G72: =Analysis!D172 -> 36498405001 | H72: =Analysis!E172 -> 2555411999 | J72: Staff 03 | K72: =Analysis!H172 -> 2283113999 | L72: =Analysis!I172 -> 0 | N72: =Analysis!J172 -> 2283113999 | P72: =Analysis!K172 -> 0
B73: Customer 04 | D73: =Analysis!B173 -> 3.6531814e+09 | F73: =Analysis!C173 -> 4505176911 | G73: =Analysis!D173 -> 1977501387 | H73: =Analysis!E173 -> 1675680000 | J73: Staff 04 | K73: =Analysis!H173 -> 43462950 | L73: =Analysis!I173 -> 0 | N73: =Analysis!J173 -> 43462950 | P73: =Analysis!K173 -> 0
B74: Customer 05 | D74: =Analysis!B174 -> 43462950 | F74: =Analysis!C174 -> 0 | G74: =Analysis!D174 -> 43462950 | H74: =Analysis!E174 -> 0 | J74: Staff 05 | K74: =Analysis!H174 -> 324663 | L74: =Analysis!I174 -> 333943 | N74: =Analysis!J174 -> 324663 | P74: =Analysis!K174 -> 0
B75: Customer 06 | D75: =Analysis!B175 -> 324663 | F75: =Analysis!C175 -> 333943 | G75: =Analysis!D175 -> 324663 | H75: =Analysis!E175 -> 0 | J75: Staff 06 | K75: =Analysis!H175 -> 4021632000 | L75: =Analysis!I175 -> 4099303796 | N75: =Analysis!J175 -> 0 | P75: =Analysis!K175 -> 4021632000
B76: Customer 07 | D76: =Analysis!B176 -> 4021632000 | F76: =Analysis!C176 -> 4099303796 | G76: =Analysis!D176 -> 0 | H76: =Analysis!E176 -> 4021632000

Sheet Current AR
A1: Fictional invoice details calibrated to retained public aggregate balances and chart proportions. Illustrative dates.
D3: 45777
A5: Customer | B5: Legal Name | C5: Document Number | D5: Invoice Number | E5: Invoice Date | F5: Due Date | G5: Invoice Gross Amount | H5: Receipts Applied | I5: Outstanding Balance | J5: Sales Representative | K5: Business Type | L5: Project | M5: Description | N5: Promised Payment Date | O5: Last Contact | P5: Next Action | Q5: Days Overdue | R5: Customer / Staff Match | S5: Selected Balance | T5: Selected Overdue | U5: Status Match | V5: Filtered Balance | W5: Overdue Days × Balance | Y5: Stable Document Key
A6: Customer 01 | B6: Fictional Customer 01 | C6: CAL-current-001 | D6: 000001 | E6: 45724 | F6: 45769 | G6: 8.6911811e+08 | H6: 2.3472533e+08 | I6: 6.3439278e+08 | J6: Staff 01 | K6: Illustrative business | L6: Demo project 2 | M6: Fictional receivable | P6: Review assigned fictional balance | Q6: =IF(ISNUMBER(F6),Dashboard!$D$2-F6,"") -> 8 | R6: =IF(AND(OR(Dashboard!$P$1="All",A6=Dashboard!$P$1),OR(Dashboard!$P$2="All",J6=Dashboard!$P$2)),1,0) -> 1 | S6: =I6*R6 -> 6.3439278e+08 | T6: =IF(AND(ISNUMBER(Q6),Q6>0),S6,0) -> 6.3439278e+08 | U6: =IF(OR(Dashboard!$P$3="All",AND(Dashboard!$P$3="Not due",Q6<0),AND(Dashboard!$P$3="Due in 10 days",Q6>=-10,Q6<=0),AND(Dashboard!$P$3="Due in 30 days",Q6>=-30,Q6<=0),AND(Dashboard!$P$3="Overdue 1-60 days",Q6>0,Q6<=60),AND(Dashboard!$P$3="Over 60 days",Q6>60),AND(Dashboard!$P$3="All overdue",Q6>0)),1,0) -> 1 | V6: =S6*U6 -> 6.3439278e+08 | W6: =IF(Q6>0,T6*Q6,0) -> 5.0751422e+09 | X6: =IF(V6>0,COUNTIF($V$6:V6,">0"),"") -> 1 | Y6: =C6&"|"&D6 -> CAL-current-001|000001
A7: Customer 01 | B7: Fictional Customer 01 | C7: CAL-current-002 | D7: 000002 | E7: 45709 | F7: 45769 | G7: 4.7906304e+08 | H7: 129381988 | I7: 3.4968105e+08 | J7: Staff 01 | K7: Illustrative business | L7: Demo project 3 | M7: Fictional receivable | P7: Review assigned fictional balance | Q7: =IF(ISNUMBER(F7),Dashboard!$D$2-F7,"") -> 8 | R7: =IF(AND(OR(Dashboard!$P$1="All",A7=Dashboard!$P$1),OR(Dashboard!$P$2="All",J7=Dashboard!$P$2)),1,0) -> 1 | S7: =I7*R7 -> 3.4968105e+08 | T7: =IF(AND(ISNUMBER(Q7),Q7>0),S7,0) -> 3.4968105e+08 | U7: =IF(OR(Dashboard!$P$3="All",AND(Dashboard!$P$3="Not due",Q7<0),AND(Dashboard!$P$3="Due in 10 days",Q7>=-10,Q7<=0),AND(Dashboard!$P$3="Due in 30 days",Q7>=-30,Q7<=0),AND(Dashboard!$P$3="Overdue 1-60 days",Q7>0,Q7<=60),AND(Dashboard!$P$3="Over 60 days",Q7>60),AND(Dashboard!$P$3="All overdue",Q7>0)),1,0) -> 1 | V7: =S7*U7 -> 3.4968105e+08 | W7: =IF(Q7>0,T7*Q7,0) -> 2.7974484e+09 | X7: =IF(V7>0,COUNTIF($V$6:V7,">0"),"") -> 2 | Y7: =C7&"|"&D7 -> CAL-current-002|000002
A8: Customer 01 | B8: Fictional Customer 01 | C8: CAL-current-003 | D8: 000003 | E8: 45724 | F8: 45769 | G8: 6.9609411e+08 | H8: 1.3016394e+08 | I8: 5.6593017e+08 | J8: Staff 01 | K8: Illustrative business | L8: Demo project 4 | M8: Fictional receivable | P8: Review assigned fictional balance | Q8: =IF(ISNUMBER(F8),Dashboard!$D$2-F8,"") -> 8 | R8: =IF(AND(OR(Dashboard!$P$1="All",A8=Dashboard!$P$1),OR(Dashboard!$P$2="All",J8=Dashboard!$P$2)),1,0) -> 1 | S8: =I8*R8 -> 5.6593017e+08 | T8: =IF(AND(ISNUMBER(Q8),Q8>0),S8,0) -> 5.6593017e+08 | U8: =IF(OR(Dashboard!$P$3="All",AND(Dashboard!$P$3="Not due",Q8<0),AND(Dashboard!$P$3="Due in 10 days",Q8>=-10,Q8<=0),AND(Dashboard!$P$3="Due in 30 days",Q8>=-30,Q8<=0),AND(Dashboard!$P$3="Overdue 1-60 days",Q8>0,Q8<=60),AND(Dashboard!$P$3="Over 60 days",Q8>60),AND(Dashboard!$P$3="All overdue",Q8>0)),1,0) -> 1 | V8: =S8*U8 -> 5.6593017e+08 | W8: =IF(Q8>0,T8*Q8,0) -> 4.5274414e+09 | X8: =IF(V8>0,COUNTIF($V$6:V8,">0"),"") -> 3 | Y8: =C8&"|"&D8 -> CAL-current-003|000003
A9: Customer 01 | B9: Fictional Customer 01 | C9: CAL-current-004 | D9: 000004 | E9: 45756 | F9: 45801 | G9: 616964430 | H9: 166625430 | I9: 450339000 | J9: Staff 01 | K9: Illustrative business | L9: Demo project 1 | M9: Fictional receivable | P9: Review assigned fictional balance | Q9: =IF(ISNUMBER(F9),Dashboard!$D$2-F9,"") -> -24 | R9: =IF(AND(OR(Dashboard!$P$1="All",A9=Dashboard!$P$1),OR(Dashboard!$P$2="All",J9=Dashboard!$P$2)),1,0) -> 1 | S9: =I9*R9 -> 450339000 | T9: =IF(AND(ISNUMBER(Q9),Q9>0),S9,0) -> 0 | U9: =IF(OR(Dashboard!$P$3="All",AND(Dashboard!$P$3="Not due",Q9<0),AND(Dashboard!$P$3="Due in 10 days",Q9>=-10,Q9<=0),AND(Dashboard!$P$3="Due in 30 days",Q9>=-30,Q9<=0),AND(Dashboard!$P$3="Overdue 1-60 days",Q9>0,Q9<=60),AND(Dashboard!$P$3="Over 60 days",Q9>60),AND(Dashboard!$P$3="All overdue",Q9>0)),1,0) -> 1 | V9: =S9*U9 -> 450339000 | W9: =IF(Q9>0,T9*Q9,0) -> 0 | X9: =IF(V9>0,COUNTIF($V$6:V9,">0"),"") -> 4 | Y9: =C9&"|"&D9 -> CAL-current-004|000004
A10: Customer 02 | B10: Fictional Customer 02 | C10: CAL-current-005 | D10: 000005 | E10: 45798 | F10: 45828 | G10: 9.4245796e+08 | H10: 1.7623198e+08 | I10: 7.6622599e+08 | J10: Staff 03 | K10: Illustrative business | L10: Demo project 2 | M10: Fictional receivable | P10: Review assigned fictional balance | Q10: =IF(ISNUMBER(F10),Dashboard!$D$2-F10,"") -> -51 | R10: =IF(AND(OR(Dashboard!$P$1="All",A10=Dashboard!$P$1),OR(Dashboard!$P$2="All",J10=Dashboard!$P$2)),1,0) -> 1 | S10: =I10*R10 -> 7.6622599e+08 | T10: =IF(AND(ISNUMBER(Q10),Q10>0),S10,0) -> 0 | U10: =IF(OR(Dashboard!$P$3="All",AND(Dashboard!$P$3="Not due",Q10<0),AND(Dashboard!$P$3="Due in 10 days",Q10>=-10,Q10<=0),AND(Dashboard!$P$3="Due in 30 days",Q10>=-30,Q10<=0),AND(Dashboard!$P$3="Overdue 1-60 days",Q10>0,Q10<=60),AND(Dashboard!$P$3="Over 60 days",Q10>60),AND(Dashboard!$P$3="All overdue",Q10>0)),1,0) -> 1 | V10: =S10*U10 -> 7.6622599e+08 | W10: =IF(Q10>0,T10*Q10,0) -> 0 | X10: =IF(V10>0,COUNTIF($V$6:V10,">0"),"") -> 5 | Y10: =C10&"|"&D10 -> CAL-current-005|000005
A11: Customer 02 | B11: Fictional Customer 02 | C11: CAL-current-006 | D11: 000006 | E11: 45768 | F11: 45828 | G11: 5.4363263e+08 | H11: 1.4682049e+08 | I11: 3.9681214e+08 | J11: Staff 03 | K11: Illustrative business | L11: Demo project 3 | M11: Fictional receivable | P11: Review assigned fictional balance | Q11: =IF(ISNUMBER(F11),Dashboard!$D$2-F11,"") -> -51 | R11: =IF(AND(OR(Dashboard!$P$1="All",A11=Dashboard!$P$1),OR(Dashboard!$P$2="All",J11=Dashboard!$P$2)),1,0) -> 1 | S11: =I11*R11 -> 3.9681214e+08 | T11: =IF(AND(ISNUMBER(Q11),Q11>0),S11,0) -> 0 | U11: =IF(OR(Dashboard!$P$3="All",AND(Dashboard!$P$3="Not due",Q11<0),AND(Dashboard!$P$3="Due in 10 days",Q11>=-10,Q11<=0),AND(Dashboard!$P$3="Due in 30 days",Q11>=-30,Q11<=0),AND(Dashboard!$P$3="Overdue 1-60 days",Q11>0,Q11<=60),AND(Dashboard!$P$3="Over 60 days",Q11>60),AND(Dashboard!$P$3="All overdue",Q11>0)),1,0) -> 1 | V11: =S11*U11 -> 3.9681214e+08 | W11: =IF(Q11>0,T11*Q11,0) -> 0 | X11: =IF(V11>0,COUNTIF($V$6:V11,">0"),"") -> 6 | Y11: =C11&"|"&D11 -> CAL-current-006|000006
A12: Customer 02 | B12: Fictional Customer 02 | C12: CAL-current-007 | D12: 000007 | E12: 45782 | F12: 45827 | G12: 4.2627624e+08 | H12: 45672455 | I12: 3.8060379e+08 | J12: Staff 03 | K12: Illustrative business | L12: Demo project 4 | M12: Fictional receivable | P12: Review assigned fictional balance | Q12: =IF(ISNUMBER(F12),Dashboard!$D$2-F12,"") -> -50 | R12: =IF(AND(OR(Dashboard!$P$1="All",A12=Dashboard!$P$1),OR(Dashboard!$P$2="All",J12=Dashboard!$P$2)),1,0) -> 1 | S12: =I12*R12 -> 3.8060379e+08 | T12: =IF(AND(ISNUMBER(Q12),Q12>0),S12,0) -> 0 | U12: =IF(OR(Dashboard!$P$3="All",AND(Dashboard!$P$3="Not due",Q12<0),AND(Dashboard!$P$3="Due in 10 days",Q12>=-10,Q12<=0),AND(Dashboard!$P$3="Due in 30 days",Q12>=-30,Q12<=0),AND(Dashboard!$P$3="Overdue 1-60 days",Q12>0,Q12<=60),AND(Dashboard!$P$3="Over 60 days",Q12>60),AND(Dashboard!$P$3="All overdue",Q12>0)),1,0) -> 1 | V12: =S12*U12 -> 3.8060379e+08 | W12: =IF(Q12>0,T12*Q12,0) -> 0 | X12: =IF(V12>0,COUNTIF($V$6:V12,">0"),"") -> 7 | Y12: =C12&"|"&D12 -> CAL-current-007|000007
A13: Customer 02 | B13: Fictional Customer 02 | C13: CAL-current-008 | D13: 000008 | E13: 45767 | F13: 45827 | G13: 9.0955066e+08 | H13: 1.7007858e+08 | I13: 7.3947208e+08 | J13: Staff 03 | K13: Illustrative business | L13: Demo project 1 | M13: Fictional receivable | P13: Review assigned fictional balance | Q13: =IF(ISNUMBER(F13),Dashboard!$D$2-F13,"") -> -50 | R13: =IF(AND(OR(Dashboard!$P$1="All",A13=Dashboard!$P$1),OR(Dashboard!$P$2="All",J13=Dashboard!$P$2)),1,0) -> 1 | S13: =I13*R13 -> 7.3947208e+08 | T13: =IF(AND(ISNUMBER(Q13),Q13>0),S13,0) -> 0 | U13: =IF(OR(Dashboard!$P$3="All",AND(Dashboard!$P$3="Not due",Q13<0),AND(Dashboard!$P$3="Due in 10 days",Q13>=-10,Q13<=0),AND(Dashboard!$P$3="Due in 30 days",Q13>=-30,Q13<=0),AND(Dashboard!$P$3="Overdue 1-60 days",Q13>0,Q13<=60),AND(Dashboard!$P$3="Over 60 days",Q13>60),AND(Dashboard!$P$3="All overdue",Q13>0)),1,0) -> 1 | V13: =S13*U13 -> 7.3947208e+08 | W13: =IF(Q13>0,T13*Q13,0) -> 0 | X13: =IF(V13>0,COUNTIF($V$6:V13,">0"),"") -> 8 | Y13: =C13&"|"&D13 -> CAL-current-008|000008
A14: Customer 03 | B14: Fictional Customer 03 | C14: CAL-current-009 | D14: 000009 | E14: 45683 | F14: 45743 | G14: 4.0624392e+08 | H14: 43526135 | I14: 362717789 | J14: Staff 01 | K14: Illustrative business | L14: Demo project 2 | M14: Fictional receivable | P14: Review assigned fictional balance | Q14: =IF(ISNUMBER(F14),Dashboard!$D$2-F14,"") -> 34 | R14: =IF(AND(OR(Dashboard!$P$1="All",A14=Dashboard!$P$1),OR(Dashboard!$P$2="All",J14=Dashboard!$P$2)),1,0) -> 1 | S14: =I14*R14 -> 362717789 | T14: =IF(AND(ISNUMBER(Q14),Q14>0),S14,0) -> 362717789 | U14: =IF(OR(Dashboard!$P$3="All",AND(Dashboard!$P$3="Not due",Q14<0),AND(Dashboard!$P$3="Due in 10 days",Q14>=-10,Q14<=0),AND(Dashboard!$P$3="Due in 30 days",Q14>=-30,Q14<=0),AND(Dashboard!$P$3="Overdue 1-60 days",Q14>0,Q14<=60),AND(Dashboard!$P$3="Over 60 days",Q14>60),AND(Dashboard!$P$3="All overdue",Q14>0)),1,0) -> 1 | V14: =S14*U14 -> 362717789 | W14: =IF(Q14>0,T14*Q14,0) -> 12332404826 | X14: =IF(V14>0,COUNTIF($V$6:V14,">0"),"") -> 9 | Y14: =C14&"|"&D14 -> CAL-current-009|000009
A15: Customer 03 | B15: Fictional Customer 03 | C15: CAL-current-010 | D15: 000010 | E15: 45697 | F15: 45742 | G15: 2.2504917e+08 | H15: 42082365 | I15: 182966804 | J15: Staff 01 | K15: Illustrative business | L15: Demo project 3 | M15: Fictional receivable | P15: Review assigned fictional balance | Q15: =IF(ISNUMBER(F15),Dashboard!$D$2-F15,"") -> 35 | R15: =IF(AND(OR(Dashboard!$P$1="All",A15=Dashboard!$P$1),OR(Dashboard!$P$2="All",J15=Dashboard!$P$2)),1,0) -> 1 | S15: =I15*R15 -> 182966804 | T15: =IF(AND(ISNUMBER(Q15),Q15>0),S15,0) -> 182966804 | U15: =IF(OR(Dashboard!$P$3="All",AND(Dashboard!$P$3="Not due",Q15<0),AND(Dashboard!$P$3="Due in 10 days",Q15>=-10,Q15<=0),AND(Dashboard!$P$3="Due in 30 days",Q15>=-30,Q15<=0),AND(Dashboard!$P$3="Overdue 1-60 days",Q15>0,Q15<=60),AND(Dashboard!$P$3="Over 60 days",Q15>60),AND(Dashboard!$P$3="All overdue",Q15>0)),1,0) -> 1 | V15: =S15*U15 -> 182966804 | W15: =IF(Q15>0,T15*Q15,0) -> 6403838140 | X15: =IF(V15>0,COUNTIF($V$6:V15,">0"),"") -> 10 | Y15: =C15&"|"&D15 -> CAL-current-010|000010
A16: Customer 03 | B16: Fictional Customer 03 | C16: CAL-current-011 | D16: 000011 | E16: 45721 | F16: 45766 | G16: 5.8855971e+08 | H16: 1.5895408e+08 | I16: 4.2960563e+08 | J16: Staff 01 | K16: Illustrative business | L16: Demo project 4 | M16: Fictional receivable | P16: Review assigned fictional balance | Q16: =IF(ISNUMBER(F16),Dashboard!$D$2-F16,"") -> 11 | R16: =IF(AND(OR(Dashboard!$P$1="All",A16=Dashboard!$P$1),OR(Dashboard!$P$2="All",J16=Dashboard!$P$2)),1,0) -> 1 | S16: =I16*R16 -> 4.2960563e+08 | T16: =IF(AND(ISNUMBER(Q16),Q16>0),S16,0) -> 4.2960563e+08 | U16: =IF(OR(Dashboard!$P$3="All",AND(Dashboard!$P$3="Not due",Q16<0),AND(Dashboard!$P$3="Due in 10 days",Q16>=-10,Q16<=0),AND(Dashboard!$P$3="Due in 30 days",Q16>=-30,Q16<=0),AND(Dashboard!$P$3="Overdue 1-60 days",Q16>0,Q16<=60),AND(Dashboard!$P$3="Over 60 days",Q16>60),AND(Dashboard!$P$3="All overdue",Q16>0)),1,0) -> 1 | V16: =S16*U16 -> 4.2960563e+08 | W16: =IF(Q16>0,T16*Q16,0) -> 4.7256619e+09 | X16: =IF(V16>0,COUNTIF($V$6:V16,">0"),"") -> 11 | Y16: =C16&"|"&D16 -> CAL-current-011|000011
A17: Customer 03 | B17: Fictional Customer 03 | C17: CAL-current-012 | D17: 000012 | E17: 45721 | F17: 45766 | G17: 5.1722605e+08 | H17: 55417077 | I17: 4.6180898e+08 | J17: Staff 01 | K17: Illustrative business | L17: Demo project 1 | M17: Fictional receivable | P17: Review assigned fictional balance | Q17: =IF(ISNUMBER(F17),Dashboard!$D$2-F17,"") -> 11 | R17: =IF(AND(OR(Dashboard!$P$1="All",A17=Dashboard!$P$1),OR(Dashboard!$P$2="All",J17=Dashboard!$P$2)),1,0) -> 1 | S17: =I17*R17 -> 4.6180898e+08 | T17: =IF(AND(ISNUMBER(Q17),Q17>0),S17,0) -> 4.6180898e+08 | U17: =IF(OR(Dashboard!$P$3="All",AND(Dashboard!$P$3="Not due",Q17<0),AND(Dashboard!$P$3="Due in 10 days",Q17>=-10,Q17<=0),AND(Dashboard!$P$3="Due in 30 days",Q17>=-30,Q17<=0),AND(Dashboard!$P$3="Overdue 1-60 days",Q17>0,Q17<=60),AND(Dashboard!$P$3="Over 60 days",Q17>60),AND(Dashboard!$P$3="All overdue",Q17>0)),1,0) -> 1 | V17: =S17*U17 -> 4.6180898e+08 | W17: =IF(Q17>0,T17*Q17,0) -> 5.0798987e+09 | X17: =IF(V17>0,COUNTIF($V$6:V17,">0"),"") -> 12 | Y17: =C17&"|"&D17 -> CAL-current-012|000012
... A103: Customer 07 | B103: Fictional Customer 07 | C103: CAL-current-098 | D103: 000098 | E103: 45641 | F103: 45701 | G103: 4504227840 | H103: 482595840 | I103: 4021632000 | J103: Staff 06 | K103: Illustrative business | L103: Demo project 3 | M103: Fictional receivable | P103: Review assigned fictional balance | Q103: =IF(ISNUMBER(F103),Dashboard!$D$2-F103,"") -> 76 | R103: =IF(AND(OR(Dashboard!$P$1="All",A103=Dashboard!$P$1),OR(Dashboard!$P$2="All",J103=Dashboard!$P$2)),1,0) -> 1 | S103: =I103*R103 -> 4021632000 | T103: =IF(AND(ISNUMBER(Q103),Q103>0),S103,0) -> 4021632000 | U103: =IF(OR(Dashboard!$P$3="All",AND(Dashboard!$P$3="Not due",Q103<0),AND(Dashboard!$P$3="Due in 10 days",Q103>=-10,Q103<=0),AND(Dashboard!$P$3="Due in 30 days",Q103>=-30,Q103<=0),AND(Dashboard!$P$3="Overdue 1-60 days",Q103>0,Q103<=60),AND(Dashboard!$P$3="Over 60 days",Q103>60),AND(Dashboard!$P$3="All overdue",Q103>0)),1,0) -> 1 | V103: =S103*U103 -> 4021632000 | W103: =IF(Q103>0,T103*Q103,0) -> 305644032000 | X103: =IF(V103>0,COUNTIF($V$6:V103,">0"),"") -> 98 | Y103: =C103&"|"&D103 -> CAL-current-098|000098

Sheet Prior AR
A1: Fictional invoice details calibrated to retained public aggregate balances and chart proportions. Illustrative dates.
D3: 45747
A5: Customer | B5: Legal Name | C5: Document Number | D5: Invoice Number | E5: Invoice Date | F5: Due Date | G5: Invoice Gross Amount | H5: Receipts Applied | I5: Outstanding Balance | J5: Sales Representative | K5: Business Type | L5: Project | M5: Description | N5: Promised Payment Date | O5: Last Contact | P5: Next Action | Q5: Days Overdue | R5: Customer / Staff Match | S5: Selected Balance | T5: Selected Overdue | U5: Status Match | V5: Filtered Balance | W5: Overdue Days × Balance
A6: Customer 01 | B6: Fictional Customer 01 | C6: CAL-prior-001 | D6: 000001 | E6: 45710 | F6: 45755 | G6: 9.2131177e+08 | H6: 98711975 | I6: 8.2259979e+08 | J6: Staff 01 | K6: Illustrative business | L6: Demo project 2 | M6: Fictional receivable | P6: Review assigned fictional balance | Q6: =IF(ISNUMBER(F6),$D$3-F6,"") -> -8 | R6: =IF(AND(OR(Dashboard!$P$1="All",A6=Dashboard!$P$1),OR(Dashboard!$P$2="All",J6=Dashboard!$P$2)),1,0) -> 1 | S6: =I6*R6 -> 8.2259979e+08 | T6: =IF(AND(ISNUMBER(Q6),Q6>0),S6,0) -> 0 | U6: =IF(OR(Dashboard!$P$3="All",AND(Dashboard!$P$3="Not due",Q6<0),AND(Dashboard!$P$3="Due in 10 days",Q6>=-10,Q6<=0),AND(Dashboard!$P$3="Due in 30 days",Q6>=-30,Q6<=0),AND(Dashboard!$P$3="Overdue 1-60 days",Q6>0,Q6<=60),AND(Dashboard!$P$3="Over 60 days",Q6>60),AND(Dashboard!$P$3="All overdue",Q6>0)),1,0) -> 1 | V6: =S6*U6 -> 8.2259979e+08 | W6: =IF(Q6>0,T6*Q6,0) -> 0 | X6: =IF(V6>0,COUNTIF($V$6:V6,">0"),"") -> 1 | Y6: =C6&"|"&D6 -> CAL-prior-001|000001
A7: Customer 01 | B7: Fictional Customer 01 | C7: CAL-prior-002 | D7: 000002 | E7: 45710 | F7: 45755 | G7: 4.5728998e+08 | H7: 48995355 | I7: 4.0829462e+08 | J7: Staff 01 | K7: Illustrative business | L7: Demo project 3 | M7: Fictional receivable | P7: Review assigned fictional balance | Q7: =IF(ISNUMBER(F7),$D$3-F7,"") -> -8 | R7: =IF(AND(OR(Dashboard!$P$1="All",A7=Dashboard!$P$1),OR(Dashboard!$P$2="All",J7=Dashboard!$P$2)),1,0) -> 1 | S7: =I7*R7 -> 4.0829462e+08 | T7: =IF(AND(ISNUMBER(Q7),Q7>0),S7,0) -> 0 | U7: =IF(OR(Dashboard!$P$3="All",AND(Dashboard!$P$3="Not due",Q7<0),AND(Dashboard!$P$3="Due in 10 days",Q7>=-10,Q7<=0),AND(Dashboard!$P$3="Due in 30 days",Q7>=-30,Q7<=0),AND(Dashboard!$P$3="Overdue 1-60 days",Q7>0,Q7<=60),AND(Dashboard!$P$3="Over 60 days",Q7>60),AND(Dashboard!$P$3="All overdue",Q7>0)),1,0) -> 1 | V7: =S7*U7 -> 4.0829462e+08 | W7: =IF(Q7>0,T7*Q7,0) -> 0 | X7: =IF(V7>0,COUNTIF($V$6:V7,">0"),"") -> 2 | Y7: =C7&"|"&D7 -> CAL-prior-002|000002
A8: Customer 01 | B8: Fictional Customer 01 | C8: CAL-prior-003 | D8: 000003 | E8: 45695 | F8: 45755 | G8: 4.1695173e+08 | H8: 44673400 | I8: 3.7227833e+08 | J8: Staff 01 | K8: Illustrative business | L8: Demo project 4 | M8: Fictional receivable | P8: Review assigned fictional balance | Q8: =IF(ISNUMBER(F8),$D$3-F8,"") -> -8 | R8: =IF(AND(OR(Dashboard!$P$1="All",A8=Dashboard!$P$1),OR(Dashboard!$P$2="All",J8=Dashboard!$P$2)),1,0) -> 1 | S8: =I8*R8 -> 3.7227833e+08 | T8: =IF(AND(ISNUMBER(Q8),Q8>0),S8,0) -> 0 | U8: =IF(OR(Dashboard!$P$3="All",AND(Dashboard!$P$3="Not due",Q8<0),AND(Dashboard!$P$3="Due in 10 days",Q8>=-10,Q8<=0),AND(Dashboard!$P$3="Due in 30 days",Q8>=-30,Q8<=0),AND(Dashboard!$P$3="Overdue 1-60 days",Q8>0,Q8<=60),AND(Dashboard!$P$3="Over 60 days",Q8>60),AND(Dashboard!$P$3="All overdue",Q8>0)),1,0) -> 1 | V8: =S8*U8 -> 3.7227833e+08 | W8: =IF(Q8>0,T8*Q8,0) -> 0 | X8: =IF(V8>0,COUNTIF($V$6:V8,">0"),"") -> 3 | Y8: =C8&"|"&D8 -> CAL-prior-003|000003
A9: Customer 03 | B9: Fictional Customer 03 | C9: CAL-prior-004 | D9: 000004 | E9: 45657 | F9: 45702 | G9: 9.2337103e+08 | H9: 2.4937758e+08 | I9: 673993450 | J9: Staff 02 | K9: Illustrative business | L9: Demo project 1 | M9: Fictional receivable | P9: Review assigned fictional balance | Q9: =IF(ISNUMBER(F9),$D$3-F9,"") -> 45 | R9: =IF(AND(OR(Dashboard!$P$1="All",A9=Dashboard!$P$1),OR(Dashboard!$P$2="All",J9=Dashboard!$P$2)),1,0) -> 1 | S9: =I9*R9 -> 673993450 | T9: =IF(AND(ISNUMBER(Q9),Q9>0),S9,0) -> 673993450 | U9: =IF(OR(Dashboard!$P$3="All",AND(Dashboard!$P$3="Not due",Q9<0),AND(Dashboard!$P$3="Due in 10 days",Q9>=-10,Q9<=0),AND(Dashboard!$P$3="Due in 30 days",Q9>=-30,Q9<=0),AND(Dashboard!$P$3="Overdue 1-60 days",Q9>0,Q9<=60),AND(Dashboard!$P$3="Over 60 days",Q9>60),AND(Dashboard!$P$3="All overdue",Q9>0)),1,0) -> 1 | V9: =S9*U9 -> 673993450 | W9: =IF(Q9>0,T9*Q9,0) -> 30329705250 | X9: =IF(V9>0,COUNTIF($V$6:V9,">0"),"") -> 4 | Y9: =C9&"|"&D9 -> CAL-prior-004|000004
A10: Customer 03 | B10: Fictional Customer 03 | C10: CAL-prior-005 | D10: 000005 | E10: 45656 | F10: 45701 | G10: 5.661545e+08 | H10: 60659411 | I10: 505495092 | J10: Staff 02 | K10: Illustrative business | L10: Demo project 2 | M10: Fictional receivable | P10: Review assigned fictional balance | Q10: =IF(ISNUMBER(F10),$D$3-F10,"") -> 46 | R10: =IF(AND(OR(Dashboard!$P$1="All",A10=Dashboard!$P$1),OR(Dashboard!$P$2="All",J10=Dashboard!$P$2)),1,0) -> 1 | S10: =I10*R10 -> 505495092 | T10: =IF(AND(ISNUMBER(Q10),Q10>0),S10,0) -> 505495092 | U10: =IF(OR(Dashboard!$P$3="All",AND(Dashboard!$P$3="Not due",Q10<0),AND(Dashboard!$P$3="Due in 10 days",Q10>=-10,Q10<=0),AND(Dashboard!$P$3="Due in 30 days",Q10>=-30,Q10<=0),AND(Dashboard!$P$3="Overdue 1-60 days",Q10>0,Q10<=60),AND(Dashboard!$P$3="Over 60 days",Q10>60),AND(Dashboard!$P$3="All overdue",Q10>0)),1,0) -> 1 | V10: =S10*U10 -> 505495092 | W10: =IF(Q10>0,T10*Q10,0) -> 23252774232 | X10: =IF(V10>0,COUNTIF($V$6:V10,">0"),"") -> 5 | Y10: =C10&"|"&D10 -> CAL-prior-005|000005
A11: Customer 03 | B11: Fictional Customer 03 | C11: CAL-prior-006 | D11: 000006 | E11: 45662 | F11: 45707 | G11: 33892572 | H11: 9153468.3 | I11: 24739104 | J11: Staff 01 | K11: Illustrative business | L11: Demo project 3 | M11: Fictional receivable | P11: Review assigned fictional balance | Q11: =IF(ISNUMBER(F11),$D$3-F11,"") -> 40 | R11: =IF(AND(OR(Dashboard!$P$1="All",A11=Dashboard!$P$1),OR(Dashboard!$P$2="All",J11=Dashboard!$P$2)),1,0) -> 1 | S11: =I11*R11 -> 24739104 | T11: =IF(AND(ISNUMBER(Q11),Q11>0),S11,0) -> 24739104 | U11: =IF(OR(Dashboard!$P$3="All",AND(Dashboard!$P$3="Not due",Q11<0),AND(Dashboard!$P$3="Due in 10 days",Q11>=-10,Q11<=0),AND(Dashboard!$P$3="Due in 30 days",Q11>=-30,Q11<=0),AND(Dashboard!$P$3="Overdue 1-60 days",Q11>0,Q11<=60),AND(Dashboard!$P$3="Over 60 days",Q11>60),AND(Dashboard!$P$3="All overdue",Q11>0)),1,0) -> 1 | V11: =S11*U11 -> 24739104 | W11: =IF(Q11>0,T11*Q11,0) -> 9.8956414e+08 | X11: =IF(V11>0,COUNTIF($V$6:V11,">0"),"") -> 6 | Y11: =C11&"|"&D11 -> CAL-prior-006|000006
A12: Customer 03 | B12: Fictional Customer 03 | C12: CAL-prior-007 | D12: 000007 | E12: 45647 | F12: 45707 | G12: 25479688 | H12: 4764494.5 | I12: 20715193 | J12: Staff 01 | K12: Illustrative business | L12: Demo project 4 | M12: Fictional receivable | P12: Review assigned fictional balance | Q12: =IF(ISNUMBER(F12),$D$3-F12,"") -> 40 | R12: =IF(AND(OR(Dashboard!$P$1="All",A12=Dashboard!$P$1),OR(Dashboard!$P$2="All",J12=Dashboard!$P$2)),1,0) -> 1 | S12: =I12*R12 -> 20715193 | T12: =IF(AND(ISNUMBER(Q12),Q12>0),S12,0) -> 20715193 | U12: =IF(OR(Dashboard!$P$3="All",AND(Dashboard!$P$3="Not due",Q12<0),AND(Dashboard!$P$3="Due in 10 days",Q12>=-10,Q12<=0),AND(Dashboard!$P$3="Due in 30 days",Q12>=-30,Q12<=0),AND(Dashboard!$P$3="Overdue 1-60 days",Q12>0,Q12<=60),AND(Dashboard!$P$3="Over 60 days",Q12>60),AND(Dashboard!$P$3="All overdue",Q12>0)),1,0) -> 1 | V12: =S12*U12 -> 20715193 | W12: =IF(Q12>0,T12*Q12,0) -> 8.2860774e+08 | X12: =IF(V12>0,COUNTIF($V$6:V12,">0"),"") -> 7 | Y12: =C12&"|"&D12 -> CAL-prior-007|000007
A13: Customer 03 | B13: Fictional Customer 03 | C13: CAL-prior-008 | D13: 000008 | E13: 45646 | F13: 45706 | G13: 2.4959979e+08 | H13: 26742834 | I13: 2.2285695e+08 | J13: Staff 01 | K13: Illustrative business | L13: Demo project 1 | M13: Fictional receivable | P13: Review assigned fictional balance | Q13: =IF(ISNUMBER(F13),$D$3-F13,"") -> 41 | R13: =IF(AND(OR(Dashboard!$P$1="All",A13=Dashboard!$P$1),OR(Dashboard!$P$2="All",J13=Dashboard!$P$2)),1,0) -> 1 | S13: =I13*R13 -> 2.2285695e+08 | T13: =IF(AND(ISNUMBER(Q13),Q13>0),S13,0) -> 2.2285695e+08 | U13: =IF(OR(Dashboard!$P$3="All",AND(Dashboard!$P$3="Not due",Q13<0),AND(Dashboard!$P$3="Due in 10 days",Q13>=-10,Q13<=0),AND(Dashboard!$P$3="Due in 30 days",Q13>=-30,Q13<=0),AND(Dashboard!$P$3="Overdue 1-60 days",Q13>0,Q13<=60),AND(Dashboard!$P$3="Over 60 days",Q13>60),AND(Dashboard!$P$3="All overdue",Q13>0)),1,0) -> 1 | V13: =S13*U13 -> 2.2285695e+08 | W13: =IF(Q13>0,T13*Q13,0) -> 9.1371351e+09 | X13: =IF(V13>0,COUNTIF($V$6:V13,">0"),"") -> 8 | Y13: =C13&"|"&D13 -> CAL-prior-008|000008
A14: Customer 03 | B14: Fictional Customer 03 | C14: CAL-prior-009 | D14: 000009 | E14: 45661 | F14: 45706 | G14: 2.5509087e+08 | H14: 47699919 | I14: 2.0739095e+08 | J14: Staff 01 | K14: Illustrative business | L14: Demo project 2 | M14: Fictional receivable | P14: Review assigned fictional balance | Q14: =IF(ISNUMBER(F14),$D$3-F14,"") -> 41 | R14: =IF(AND(OR(Dashboard!$P$1="All",A14=Dashboard!$P$1),OR(Dashboard!$P$2="All",J14=Dashboard!$P$2)),1,0) -> 1 | S14: =I14*R14 -> 2.0739095e+08 | T14: =IF(AND(ISNUMBER(Q14),Q14>0),S14,0) -> 2.0739095e+08 | U14: =IF(OR(Dashboard!$P$3="All",AND(Dashboard!$P$3="Not due",Q14<0),AND(Dashboard!$P$3="Due in 10 days",Q14>=-10,Q14<=0),AND(Dashboard!$P$3="Due in 30 days",Q14>=-30,Q14<=0),AND(Dashboard!$P$3="Overdue 1-60 days",Q14>0,Q14<=60),AND(Dashboard!$P$3="Over 60 days",Q14>60),AND(Dashboard!$P$3="All overdue",Q14>0)),1,0) -> 1 | V14: =S14*U14 -> 2.0739095e+08 | W14: =IF(Q14>0,T14*Q14,0) -> 8.503029e+09 | X14: =IF(V14>0,COUNTIF($V$6:V14,">0"),"") -> 9 | Y14: =C14&"|"&D14 -> CAL-prior-009|000009
A15: Customer 03 | B15: Fictional Customer 03 | C15: CAL-prior-010 | D15: 000010 | E15: 45662 | F15: 45722 | G15: 5.661545e+08 | H15: 60659411 | I15: 505495089 | J15: Staff 02 | K15: Illustrative business | L15: Demo project 3 | M15: Fictional receivable | P15: Review assigned fictional balance | Q15: =IF(ISNUMBER(F15),$D$3-F15,"") -> 25 | R15: =IF(AND(OR(Dashboard!$P$1="All",A15=Dashboard!$P$1),OR(Dashboard!$P$2="All",J15=Dashboard!$P$2)),1,0) -> 1 | S15: =I15*R15 -> 505495089 | T15: =IF(AND(ISNUMBER(Q15),Q15>0),S15,0) -> 505495089 | U15: =IF(OR(Dashboard!$P$3="All",AND(Dashboard!$P$3="Not due",Q15<0),AND(Dashboard!$P$3="Due in 10 days",Q15>=-10,Q15<=0),AND(Dashboard!$P$3="Due in 30 days",Q15>=-30,Q15<=0),AND(Dashboard!$P$3="Overdue 1-60 days",Q15>0,Q15<=60),AND(Dashboard!$P$3="Over 60 days",Q15>60),AND(Dashboard!$P$3="All overdue",Q15>0)),1,0) -> 1 | V15: =S15*U15 -> 505495089 | W15: =IF(Q15>0,T15*Q15,0) -> 12637377225 | X15: =IF(V15>0,COUNTIF($V$6:V15,">0"),"") -> 10 | Y15: =C15&"|"&D15 -> CAL-prior-010|000010
A16: Customer 03 | B16: Fictional Customer 03 | C16: CAL-prior-011 | D16: 000011 | E16: 45685 | F16: 45730 | G16: 6.8085984e+08 | H16: 1.2731525e+08 | I16: 553544584 | J16: Staff 01 | K16: Illustrative business | L16: Demo project 4 | M16: Fictional receivable | P16: Review assigned fictional balance | Q16: =IF(ISNUMBER(F16),$D$3-F16,"") -> 17 | R16: =IF(AND(OR(Dashboard!$P$1="All",A16=Dashboard!$P$1),OR(Dashboard!$P$2="All",J16=Dashboard!$P$2)),1,0) -> 1 | S16: =I16*R16 -> 553544584 | T16: =IF(AND(ISNUMBER(Q16),Q16>0),S16,0) -> 553544584 | U16: =IF(OR(Dashboard!$P$3="All",AND(Dashboard!$P$3="Not due",Q16<0),AND(Dashboard!$P$3="Due in 10 days",Q16>=-10,Q16<=0),AND(Dashboard!$P$3="Due in 30 days",Q16>=-30,Q16<=0),AND(Dashboard!$P$3="Overdue 1-60 days",Q16>0,Q16<=60),AND(Dashboard!$P$3="Over 60 days",Q16>60),AND(Dashboard!$P$3="All overdue",Q16>0)),1,0) -> 1 | V16: =S16*U16 -> 553544584 | W16: =IF(Q16>0,T16*Q16,0) -> 9410257928 | X16: =IF(V16>0,COUNTIF($V$6:V16,">0"),"") -> 11 | Y16: =C16&"|"&D16 -> CAL-prior-011|000011
A17: Customer 03 | B17: Fictional Customer 03 | C17: CAL-prior-012 | D17: 000012 | E17: 45699 | F17: 45729 | G17: 70077466 | H17: 13103916 | I17: 56973549 | J17: Staff 01 | K17: Illustrative business | L17: Demo project 1 | M17: Fictional receivable | P17: Review assigned fictional balance | Q17: =IF(ISNUMBER(F17),$D$3-F17,"") -> 18 | R17: =IF(AND(OR(Dashboard!$P$1="All",A17=Dashboard!$P$1),OR(Dashboard!$P$2="All",J17=Dashboard!$P$2)),1,0) -> 1 | S17: =I17*R17 -> 56973549 | T17: =IF(AND(ISNUMBER(Q17),Q17>0),S17,0) -> 56973549 | U17: =IF(OR(Dashboard!$P$3="All",AND(Dashboard!$P$3="Not due",Q17<0),AND(Dashboard!$P$3="Due in 10 days",Q17>=-10,Q17<=0),AND(Dashboard!$P$3="Due in 30 days",Q17>=-30,Q17<=0),AND(Dashboard!$P$3="Overdue 1-60 days",Q17>0,Q17<=60),AND(Dashboard!$P$3="Over 60 days",Q17>60),AND(Dashboard!$P$3="All overdue",Q17>0)),1,0) -> 1 | V17: =S17*U17 -> 56973549 | W17: =IF(Q17>0,T17*Q17,0) -> 1.0255239e+09 | X17: =IF(V17>0,COUNTIF($V$6:V17,">0"),"") -> 12 | Y17: =C17&"|"&D17 -> CAL-prior-012|000012
... A85: Customer 06 | B85: Fictional Customer 06 | C85: CAL-prior-080 | D85: 000080 | E85: 45740 | F85: 45785 | G85: 374016.16 | H85: 40073.16 | I85: 333943 | J85: Staff 05 | K85: Illustrative business | L85: Demo project 1 | M85: Fictional receivable | P85: Review assigned fictional balance | Q85: =IF(ISNUMBER(F85),$D$3-F85,"") -> -38 | R85: =IF(AND(OR(Dashboard!$P$1="All",A85=Dashboard!$P$1),OR(Dashboard!$P$2="All",J85=Dashboard!$P$2)),1,0) -> 1 | S85: =I85*R85 -> 333943 | T85: =IF(AND(ISNUMBER(Q85),Q85>0),S85,0) -> 0 | U85: =IF(OR(Dashboard!$P$3="All",AND(Dashboard!$P$3="Not due",Q85<0),AND(Dashboard!$P$3="Due in 10 days",Q85>=-10,Q85<=0),AND(Dashboard!$P$3="Due in 30 days",Q85>=-30,Q85<=0),AND(Dashboard!$P$3="Overdue 1-60 days",Q85>0,Q85<=60),AND(Dashboard!$P$3="Over 60 days",Q85>60),AND(Dashboard!$P$3="All overdue",Q85>0)),1,0) -> 1 | V85: =S85*U85 -> 333943 | W85: =IF(Q85>0,T85*Q85,0) -> 0 | X85: =IF(V85>0,COUNTIF($V$6:V85,">0"),"") -> 80 | Y85: =C85&"|"&D85 -> CAL-prior-080|000080

Sheet Analysis
A1: ACCOUNTS RECEIVABLE RECONCILIATION & RISK ANALYSIS | R1: 0 | S1: 0 | Z1: 0 | AA1: 0 | AH1: 0 | AI1: 0
R2: =-COS(PI()*B16) -> -0.93739426 | S2: =SIN(PI()*B16) -> 0.34827002 | Z2: =-COS(PI()*B17) -> -0.9695375 | AA2: =SIN(PI()*B17) -> 0.24494294 | AH2: =-COS(PI()*B18) -> -0.8235326 | AI2: =SIN(PI()*B18) -> 0.56726895
R3: 0 | S3: 0 | Z3: 0 | AA3: 0 | AH3: 0 | AI3: 0
A5: KPI Metric | B5: Current Cycle | C5: Prior Cycle | D5: Variance | E5: Change (%) | R5: -1 | S5: =SQRT(MAX(0,1-R5^2)) -> 0 | T5: =IF(ISNUMBER($B$16),IF(AND($C$16=1,R5<=-COS(PI()*$B$16)),S5,NA()),NA()) -> 0 | U5: =IF(ISNUMBER($B$16),IF(AND($C$16=2,R5<=-COS(PI()*$B$16)),S5,NA()),NA()) -> #N/A | V5: =IF(ISNUMBER($B$16),IF(AND($C$16=3,R5<=-COS(PI()*$B$16)),S5,NA()),NA()) -> #N/A | W5: =IF(ISNUMBER($B$16),IF(AND($C$16=4,R5<=-COS(PI()*$B$16)),S5,NA()),NA()) -> #N/A | X5: =IF(ISNUMBER($B$16),IF(AND($C$16=5,R5<=-COS(PI()*$B$16)),S5,NA()),NA()) -> #N/A | Y5: =IF(ISNUMBER($B$16),IF(AND(ISNUMBER($B$16),R5>=MIN(0,$R$2),R5<=MAX(0,$R$2)),IF($R$2=0,0,R5/$R$2*$S$2),NA()),NA()) -> #N/A | Z5: -1 | AA5: =SQRT(MAX(0,1-Z5^2)) -> 0 | AB5: =IF(ISNUMBER($B$17),IF(AND($C$17=1,Z5<=-COS(PI()*$B$17)),AA5,NA()),NA()) -> 0 | AC5: =IF(ISNUMBER($B$17),IF(AND($C$17=2,Z5<=-COS(PI()*$B$17)),AA5,NA()),NA()) -> #N/A | AD5: =IF(ISNUMBER($B$17),IF(AND($C$17=3,Z5<=-COS(PI()*$B$17)),AA5,NA()),NA()) -> #N/A | AE5: =IF(ISNUMBER($B$17),IF(AND($C$17=4,Z5<=-COS(PI()*$B$17)),AA5,NA()),NA()) -> #N/A | AF5: =IF(ISNUMBER($B$17),IF(AND($C$17=5,Z5<=-COS(PI()*$B$17)),AA5,NA()),NA()) -> #N/A | AG5: =IF(ISNUMBER($B$17),IF(AND(ISNUMBER($B$17),Z5>=MIN(0,$Z$2),Z5<=MAX(0,$Z$2)),IF($Z$2=0,0,Z5/$Z$2*$AA$2),NA()),NA()) -> #N/A | AH5: -1 | AI5: =SQRT(MAX(0,1-AH5^2)) -> 0 | AJ5: =IF(ISNUMBER($B$18),IF(AND($C$18=1,AH5<=-COS(PI()*$B$18)),AI5,NA()),NA()) -> 0 | AK5: =IF(ISNUMBER($B$18),IF(AND($C$18=2,AH5<=-COS(PI()*$B$18)),AI5,NA()),NA()) -> #N/A | AL5: =IF(ISNUMBER($B$18),IF(AND($C$18=3,AH5<=-COS(PI()*$B$18)),AI5,NA()),NA()) -> #N/A | AM5: =IF(ISNUMBER($B$18),IF(AND($C$18=4,AH5<=-COS(PI()*$B$18)),AI5,NA()),NA()) -> #N/A | AN5: =IF(ISNUMBER($B$18),IF(AND($C$18=5,AH5<=-COS(PI()*$B$18)),AI5,NA()),NA()) -> #N/A | AO5: =IF(ISNUMBER($B$18),IF(AND(ISNUMBER($B$18),AH5>=MIN(0,$AH$2),AH5<=MAX(0,$AH$2)),IF($AH$2=0,0,AH5/$AH$2*$AI$2),NA()),NA()) -> #N/A
A6: Total Outstanding AR | B6: =SUM('Current AR'!$S$6:$S$103) -> 51055875000 | C6: =SUM('Prior AR'!$S$6:$S$85) -> 33932519997 | D6: =IF(AND(ISNUMBER(B6),ISNUMBER(C6)),B6-C6,"n.a.") -> 17123355003 | E6: =IF(AND(ISNUMBER(C6),C6<>0,ISNUMBER(D6)),D6/C6,"n.a.") -> 0.50462963 | R6: -0.98 | S6: =SQRT(MAX(0,1-R6^2)) -> 0.19899749 | T6: =IF(ISNUMBER($B$16),IF(AND($C$16=1,R6<=-COS(PI()*$B$16)),S6,NA()),NA()) -> 0.19899749 | U6: =IF(ISNUMBER($B$16),IF(AND($C$16=2,R6<=-COS(PI()*$B$16)),S6,NA()),NA()) -> #N/A | V6: =IF(ISNUMBER($B$16),IF(AND($C$16=3,R6<=-COS(PI()*$B$16)),S6,NA()),NA()) -> #N/A | W6: =IF(ISNUMBER($B$16),IF(AND($C$16=4,R6<=-COS(PI()*$B$16)),S6,NA()),NA()) -> #N/A | X6: =IF(ISNUMBER($B$16),IF(AND($C$16=5,R6<=-COS(PI()*$B$16)),S6,NA()),NA()) -> #N/A | Y6: =IF(ISNUMBER($B$16),IF(AND(ISNUMBER($B$16),R6>=MIN(0,$R$2),R6<=MAX(0,$R$2)),IF($R$2=0,0,R6/$R$2*$S$2),NA()),NA()) -> #N/A | Z6: -0.98 | AA6: =SQRT(MAX(0,1-Z6^2)) -> 0.19899749 | AB6: =IF(ISNUMBER($B$17),IF(AND($C$17=1,Z6<=-COS(PI()*$B$17)),AA6,NA()),NA()) -> 0.19899749 | AC6: =IF(ISNUMBER($B$17),IF(AND($C$17=2,Z6<=-COS(PI()*$B$17)),AA6,NA()),NA()) -> #N/A | AD6: =IF(ISNUMBER($B$17),IF(AND($C$17=3,Z6<=-COS(PI()*$B$17)),AA6,NA()),NA()) -> #N/A | AE6: =IF(ISNUMBER($B$17),IF(AND($C$17=4,Z6<=-COS(PI()*$B$17)),AA6,NA()),NA()) -> #N/A | AF6: =IF(ISNUMBER($B$17),IF(AND($C$17=5,Z6<=-COS(PI()*$B$17)),AA6,NA()),NA()) -> #N/A | AG6: =IF(ISNUMBER($B$17),IF(AND(ISNUMBER($B$17),Z6>=MIN(0,$Z$2),Z6<=MAX(0,$Z$2)),IF($Z$2=0,0,Z6/$Z$2*$AA$2),NA()),NA()) -> #N/A | AH6: -0.98 | AI6: =SQRT(MAX(0,1-AH6^2)) -> 0.19899749 | AJ6: =IF(ISNUMBER($B$18),IF(AND($C$18=1,AH6<=-COS(PI()*$B$18)),AI6,NA()),NA()) -> 0.19899749 | AK6: =IF(ISNUMBER($B$18),IF(AND($C$18=2,AH6<=-COS(PI()*$B$18)),AI6,NA()),NA()) -> #N/A | AL6: =IF(ISNUMBER($B$18),IF(AND($C$18=3,AH6<=-COS(PI()*$B$18)),AI6,NA()),NA()) -> #N/A | AM6: =IF(ISNUMBER($B$18),IF(AND($C$18=4,AH6<=-COS(PI()*$B$18)),AI6,NA()),NA()) -> #N/A | AN6: =IF(ISNUMBER($B$18),IF(AND($C$18=5,AH6<=-COS(PI()*$B$18)),AI6,NA()),NA()) -> #N/A | AO6: =IF(ISNUMBER($B$18),IF(AND(ISNUMBER($B$18),AH6>=MIN(0,$AH$2),AH6<=MAX(0,$AH$2)),IF($AH$2=0,0,AH6/$AH$2*$AI$2),NA()),NA()) -> #N/A
A7: Overdue Debt (1–60 Days) | B7: =SUMIFS('Current AR'!$S$6:$S$103,'Current AR'!$Q$6:$Q$103,">0",'Current AR'!$Q$6:$Q$103,"<=60") -> 5781096000 | C7: =SUMIFS('Prior AR'!$S$6:$S$85,'Prior AR'!$Q$6:$Q$85,">0",'Prior AR'!$Q$6:$Q$85,"<=60") -> 5829261123 | D7: =IF(AND(ISNUMBER(B7),ISNUMBER(C7)),B7-C7,"n.a.") -> -48165123 | E7: =IF(AND(ISNUMBER(C7),C7<>0,ISNUMBER(D7)),D7/C7,"n.a.") -> -0.0082626463 | R7: -0.96 | S7: =SQRT(MAX(0,1-R7^2)) -> 0.28 | T7: =IF(ISNUMBER($B$16),IF(AND($C$16=1,R7<=-COS(PI()*$B$16)),S7,NA()),NA()) -> 0.28 | U7: =IF(ISNUMBER($B$16),IF(AND($C$16=2,R7<=-COS(PI()*$B$16)),S7,NA()),NA()) -> #N/A | V7: =IF(ISNUMBER($B$16),IF(AND($C$16=3,R7<=-COS(PI()*$B$16)),S7,NA()),NA()) -> #N/A | W7: =IF(ISNUMBER($B$16),IF(AND($C$16=4,R7<=-COS(PI()*$B$16)),S7,NA()),NA()) -> #N/A | X7: =IF(ISNUMBER($B$16),IF(AND($C$16=5,R7<=-COS(PI()*$B$16)),S7,NA()),NA()) -> #N/A | Y7: =IF(ISNUMBER($B$16),IF(AND(ISNUMBER($B$16),R7>=MIN(0,$R$2),R7<=MAX(0,$R$2)),IF($R$2=0,0,R7/$R$2*$S$2),NA()),NA()) -> #N/A | Z7: -0.96 | AA7: =SQRT(MAX(0,1-Z7^2)) -> 0.28 | AB7: =IF(ISNUMBER($B$17),IF(AND($C$17=1,Z7<=-COS(PI()*$B$17)),AA7,NA()),NA()) -> #N/A | AC7: =IF(ISNUMBER($B$17),IF(AND($C$17=2,Z7<=-COS(PI()*$B$17)),AA7,NA()),NA()) -> #N/A | AD7: =IF(ISNUMBER($B$17),IF(AND($C$17=3,Z7<=-COS(PI()*$B$17)),AA7,NA()),NA()) -> #N/A | AE7: =IF(ISNUMBER($B$17),IF(AND($C$17=4,Z7<=-COS(PI()*$B$17)),AA7,NA()),NA()) -> #N/A | AF7: =IF(ISNUMBER($B$17),IF(AND($C$17=5,Z7<=-COS(PI()*$B$17)),AA7,NA()),NA()) -> #N/A | AG7: =IF(ISNUMBER($B$17),IF(AND(ISNUMBER($B$17),Z7>=MIN(0,$Z$2),Z7<=MAX(0,$Z$2)),IF($Z$2=0,0,Z7/$Z$2*$AA$2),NA()),NA()) -> 0.24253339 | AH7: -0.96 | AI7: =SQRT(MAX(0,1-AH7^2)) -> 0.28 | AJ7: =IF(ISNUMBER($B$18),IF(AND($C$18=1,AH7<=-COS(PI()*$B$18)),AI7,NA()),NA()) -> 0.28 | AK7: =IF(ISNUMBER($B$18),IF(AND($C$18=2,AH7<=-COS(PI()*$B$18)),AI7,NA()),NA()) -> #N/A | AL7: =IF(ISNUMBER($B$18),IF(AND($C$18=3,AH7<=-COS(PI()*$B$18)),AI7,NA()),NA()) -> #N/A | AM7: =IF(ISNUMBER($B$18),IF(AND($C$18=4,AH7<=-COS(PI()*$B$18)),AI7,NA()),NA()) -> #N/A | AN7: =IF(ISNUMBER($B$18),IF(AND($C$18=5,AH7<=-COS(PI()*$B$18)),AI7,NA()),NA()) -> #N/A | AO7: =IF(ISNUMBER($B$18),IF(AND(ISNUMBER($B$18),AH7>=MIN(0,$AH$2),AH7<=MAX(0,$AH$2)),IF($AH$2=0,0,AH7/$AH$2*$AI$2),NA()),NA()) -> #N/A
A8: Doubtful Debt (>60 Days) | B8: =SUMIFS('Current AR'!$S$6:$S$103,'Current AR'!$Q$6:$Q$103,">60") -> 4021632000 | C8: =SUMIFS('Prior AR'!$S$6:$S$85,'Prior AR'!$Q$6:$Q$85,">60") -> 4099303796 | D8: =IF(AND(ISNUMBER(B8),ISNUMBER(C8)),B8-C8,"n.a.") -> -77671796 | E8: =IF(AND(ISNUMBER(C8),C8<>0,ISNUMBER(D8)),D8/C8,"n.a.") -> -0.018947558 | R8: -0.94 | S8: =SQRT(MAX(0,1-R8^2)) -> 0.34117444 | T8: =IF(ISNUMBER($B$16),IF(AND($C$16=1,R8<=-COS(PI()*$B$16)),S8,NA()),NA()) -> 0.34117444 | U8: =IF(ISNUMBER($B$16),IF(AND($C$16=2,R8<=-COS(PI()*$B$16)),S8,NA()),NA()) -> #N/A | V8: =IF(ISNUMBER($B$16),IF(AND($C$16=3,R8<=-COS(PI()*$B$16)),S8,NA()),NA()) -> #N/A | W8: =IF(ISNUMBER($B$16),IF(AND($C$16=4,R8<=-COS(PI()*$B$16)),S8,NA()),NA()) -> #N/A | X8: =IF(ISNUMBER($B$16),IF(AND($C$16=5,R8<=-COS(PI()*$B$16)),S8,NA()),NA()) -> #N/A | Y8: =IF(ISNUMBER($B$16),IF(AND(ISNUMBER($B$16),R8>=MIN(0,$R$2),R8<=MAX(0,$R$2)),IF($R$2=0,0,R8/$R$2*$S$2),NA()),NA()) -> #N/A | Z8: -0.94 | AA8: =SQRT(MAX(0,1-Z8^2)) -> 0.34117444 | AB8: =IF(ISNUMBER($B$17),IF(AND($C$17=1,Z8<=-COS(PI()*$B$17)),AA8,NA()),NA()) -> #N/A | AC8: =IF(ISNUMBER($B$17),IF(AND($C$17=2,Z8<=-COS(PI()*$B$17)),AA8,NA()),NA()) -> #N/A | AD8: =IF(ISNUMBER($B$17),IF(AND($C$17=3,Z8<=-COS(PI()*$B$17)),AA8,NA()),NA()) -> #N/A | AE8: =IF(ISNUMBER($B$17),IF(AND($C$17=4,Z8<=-COS(PI()*$B$17)),AA8,NA()),NA()) -> #N/A | AF8: =IF(ISNUMBER($B$17),IF(AND($C$17=5,Z8<=-COS(PI()*$B$17)),AA8,NA()),NA()) -> #N/A | AG8: =IF(ISNUMBER($B$17),IF(AND(ISNUMBER($B$17),Z8>=MIN(0,$Z$2),Z8<=MAX(0,$Z$2)),IF($Z$2=0,0,Z8/$Z$2*$AA$2),NA()),NA()) -> 0.23748062 | AH8: -0.94 | AI8: =SQRT(MAX(0,1-AH8^2)) -> 0.34117444 | AJ8: =IF(ISNUMBER($B$18),IF(AND($C$18=1,AH8<=-COS(PI()*$B$18)),AI8,NA()),NA()) -> 0.34117444 | AK8: =IF(ISNUMBER($B$18),IF(AND($C$18=2,AH8<=-COS(PI()*$B$18)),AI8,NA()),NA()) -> #N/A | AL8: =IF(ISNUMBER($B$18),IF(AND($C$18=3,AH8<=-COS(PI()*$B$18)),AI8,NA()),NA()) -> #N/A | AM8: =IF(ISNUMBER($B$18),IF(AND($C$18=4,AH8<=-COS(PI()*$B$18)),AI8,NA()),NA()) -> #N/A | AN8: =IF(ISNUMBER($B$18),IF(AND($C$18=5,AH8<=-COS(PI()*$B$18)),AI8,NA()),NA()) -> #N/A | AO8: =IF(ISNUMBER($B$18),IF(AND(ISNUMBER($B$18),AH8>=MIN(0,$AH$2),AH8<=MAX(0,$AH$2)),IF($AH$2=0,0,AH8/$AH$2*$AI$2),NA()),NA()) -> #N/A
A9: Total Overdue & Doubtful | B9: =B7+B8 -> 9802728000 | C9: =C7+C8 -> 9928564919 | D9: =IF(AND(ISNUMBER(B9),ISNUMBER(C9)),B9-C9,"n.a.") -> -125836919 | E9: =IF(AND(ISNUMBER(C9),C9<>0,ISNUMBER(D9)),D9/C9,"n.a.") -> -0.01267423 | R9: -0.92 | S9: =SQRT(MAX(0,1-R9^2)) -> 0.39191836 | T9: =IF(ISNUMBER($B$16),IF(AND($C$16=1,R9<=-COS(PI()*$B$16)),S9,NA()),NA()) -> #N/A | U9: =IF(ISNUMBER($B$16),IF(AND($C$16=2,R9<=-COS(PI()*$B$16)),S9,NA()),NA()) -> #N/A | V9: =IF(ISNUMBER($B$16),IF(AND($C$16=3,R9<=-COS(PI()*$B$16)),S9,NA()),NA()) -> #N/A | W9: =IF(ISNUMBER($B$16),IF(AND($C$16=4,R9<=-COS(PI()*$B$16)),S9,NA()),NA()) -> #N/A | X9: =IF(ISNUMBER($B$16),IF(AND($C$16=5,R9<=-COS(PI()*$B$16)),S9,NA()),NA()) -> #N/A | Y9: =IF(ISNUMBER($B$16),IF(AND(ISNUMBER($B$16),R9>=MIN(0,$R$2),R9<=MAX(0,$R$2)),IF($R$2=0,0,R9/$R$2*$S$2),NA()),NA()) -> 0.34180754 | Z9: -0.92 | AA9: =SQRT(MAX(0,1-Z9^2)) -> 0.39191836 | AB9: =IF(ISNUMBER($B$17),IF(AND($C$17=1,Z9<=-COS(PI()*$B$17)),AA9,NA()),NA()) -> #N/A | AC9: =IF(ISNUMBER($B$17),IF(AND($C$17=2,Z9<=-COS(PI()*$B$17)),AA9,NA()),NA()) -> #N/A | AD9: =IF(ISNUMBER($B$17),IF(AND($C$17=3,Z9<=-COS(PI()*$B$17)),AA9,NA()),NA()) -> #N/A | AE9: =IF(ISNUMBER($B$17),IF(AND($C$17=4,Z9<=-COS(PI()*$B$17)),AA9,NA()),NA()) -> #N/A | AF9: =IF(ISNUMBER($B$17),IF(AND($C$17=5,Z9<=-COS(PI()*$B$17)),AA9,NA()),NA()) -> #N/A | AG9: =IF(ISNUMBER($B$17),IF(AND(ISNUMBER($B$17),Z9>=MIN(0,$Z$2),Z9<=MAX(0,$Z$2)),IF($Z$2=0,0,Z9/$Z$2*$AA$2),NA()),NA()) -> 0.23242784 | AH9: -0.92 | AI9: =SQRT(MAX(0,1-AH9^2)) -> 0.39191836 | AJ9: =IF(ISNUMBER($B$18),IF(AND($C$18=1,AH9<=-COS(PI()*$B$18)),AI9,NA()),NA()) -> 0.39191836 | AK9: =IF(ISNUMBER($B$18),IF(AND($C$18=2,AH9<=-COS(PI()*$B$18)),AI9,NA()),NA()) -> #N/A | AL9: =IF(ISNUMBER($B$18),IF(AND($C$18=3,AH9<=-COS(PI()*$B$18)),AI9,NA()),NA()) -> #N/A | AM9: =IF(ISNUMBER($B$18),IF(AND($C$18=4,AH9<=-COS(PI()*$B$18)),AI9,NA()),NA()) -> #N/A | AN9: =IF(ISNUMBER($B$18),IF(AND($C$18=5,AH9<=-COS(PI()*$B$18)),AI9,NA()),NA()) -> #N/A | AO9: =IF(ISNUMBER($B$18),IF(AND(ISNUMBER($B$18),AH9>=MIN(0,$AH$2),AH9<=MAX(0,$AH$2)),IF($AH$2=0,0,AH9/$AH$2*$AI$2),NA()),NA()) -> #N/A
A10: Total Overdue Ratio | B10: =IF(B6=0,"n.a.",B9/B6) -> 0.192 | C10: =IF(C6=0,"n.a.",C9/C6) -> 0.29259733 | D10: =IF(AND(ISNUMBER(B10),ISNUMBER(C10)),B10-C10,"n.a.") -> -0.10059733 | E10: =IF(AND(ISNUMBER(C10),C10<>0,ISNUMBER(D10)),D10/C10,"n.a.") -> -0.3438081 | R10: -0.9 | S10: =SQRT(MAX(0,1-R10^2)) -> 0.43588989 | T10: =IF(ISNUMBER($B$16),IF(AND($C$16=1,R10<=-COS(PI()*$B$16)),S10,NA()),NA()) -> #N/A | U10: =IF(ISNUMBER($B$16),IF(AND($C$16=2,R10<=-COS(PI()*$B$16)),S10,NA()),NA()) -> #N/A | V10: =IF(ISNUMBER($B$16),IF(AND($C$16=3,R10<=-COS(PI()*$B$16)),S10,NA()),NA()) -> #N/A | W10: =IF(ISNUMBER($B$16),IF(AND($C$16=4,R10<=-COS(PI()*$B$16)),S10,NA()),NA()) -> #N/A | X10: =IF(ISNUMBER($B$16),IF(AND($C$16=5,R10<=-COS(PI()*$B$16)),S10,NA()),NA()) -> #N/A | Y10: =IF(ISNUMBER($B$16),IF(AND(ISNUMBER($B$16),R10>=MIN(0,$R$2),R10<=MAX(0,$R$2)),IF($R$2=0,0,R10/$R$2*$S$2),NA()),NA()) -> 0.33437694 | Z10: -0.9 | AA10: =SQRT(MAX(0,1-Z10^2)) -> 0.43588989 | AB10: =IF(ISNUMBER($B$17),IF(AND($C$17=1,Z10<=-COS(PI()*$B$17)),AA10,NA()),NA()) -> #N/A | AC10: =IF(ISNUMBER($B$17),IF(AND($C$17=2,Z10<=-COS(PI()*$B$17)),AA10,NA()),NA()) -> #N/A | AD10: =IF(ISNUMBER($B$17),IF(AND($C$17=3,Z10<=-COS(PI()*$B$17)),AA10,NA()),NA()) -> #N/A | AE10: =IF(ISNUMBER($B$17),IF(AND($C$17=4,Z10<=-COS(PI()*$B$17)),AA10,NA()),NA()) -> #N/A | AF10: =IF(ISNUMBER($B$17),IF(AND($C$17=5,Z10<=-COS(PI()*$B$17)),AA10,NA()),NA()) -> #N/A | AG10: =IF(ISNUMBER($B$17),IF(AND(ISNUMBER($B$17),Z10>=MIN(0,$Z$2),Z10<=MAX(0,$Z$2)),IF($Z$2=0,0,Z10/$Z$2*$AA$2),NA()),NA()) -> 0.22737506 | AH10: -0.9 | AI10: =SQRT(MAX(0,1-AH10^2)) -> 0.43588989 | AJ10: =IF(ISNUMBER($B$18),IF(AND($C$18=1,AH10<=-COS(PI()*$B$18)),AI10,NA()),NA()) -> 0.43588989 | AK10: =IF(ISNUMBER($B$18),IF(AND($C$18=2,AH10<=-COS(PI()*$B$18)),AI10,NA()),NA()) -> #N/A | AL10: =IF(ISNUMBER($B$18),IF(AND($C$18=3,AH10<=-COS(PI()*$B$18)),AI10,NA()),NA()) -> #N/A | AM10: =IF(ISNUMBER($B$18),IF(AND($C$18=4,AH10<=-COS(PI()*$B$18)),AI10,NA()),NA()) -> #N/A | AN10: =IF(ISNUMBER($B$18),IF(AND($C$18=5,AH10<=-COS(PI()*$B$18)),AI10,NA()),NA()) -> #N/A | AO10: =IF(ISNUMBER($B$18),IF(AND(ISNUMBER($B$18),AH10>=MIN(0,$AH$2),AH10<=MAX(0,$AH$2)),IF($AH$2=0,0,AH10/$AH$2*$AI$2),NA()),NA()) -> #N/A
A11: Due within 10 Days | B11: =SUMIFS('Current AR'!$S$6:$S$103,'Current AR'!$Q$6:$Q$103,">=-10",'Current AR'!$Q$6:$Q$103,"<=0") -> 3.8107966e+09 | C11: =SUMIFS('Prior AR'!$S$6:$S$85,'Prior AR'!$Q$6:$Q$85,">=-10",'Prior AR'!$Q$6:$Q$85,"<=0") -> 3345665769 | D11: =IF(AND(ISNUMBER(B11),ISNUMBER(C11)),B11-C11,"n.a.") -> 4.6513087e+08 | E11: =IF(AND(ISNUMBER(C11),C11<>0,ISNUMBER(D11)),D11/C11,"n.a.") -> 0.13902491 | R11: -0.88 | S11: =SQRT(MAX(0,1-R11^2)) -> 0.47497368 | T11: =IF(ISNUMBER($B$16),IF(AND($C$16=1,R11<=-COS(PI()*$B$16)),S11,NA()),NA()) -> #N/A | U11: =IF(ISNUMBER($B$16),IF(AND($C$16=2,R11<=-COS(PI()*$B$16)),S11,NA()),NA()) -> #N/A | V11: =IF(ISNUMBER($B$16),IF(AND($C$16=3,R11<=-COS(PI()*$B$16)),S11,NA()),NA()) -> #N/A | W11: =IF(ISNUMBER($B$16),IF(AND($C$16=4,R11<=-COS(PI()*$B$16)),S11,NA()),NA()) -> #N/A | X11: =IF(ISNUMBER($B$16),IF(AND($C$16=5,R11<=-COS(PI()*$B$16)),S11,NA()),NA()) -> #N/A | Y11: =IF(ISNUMBER($B$16),IF(AND(ISNUMBER($B$16),R11>=MIN(0,$R$2),R11<=MAX(0,$R$2)),IF($R$2=0,0,R11/$R$2*$S$2),NA()),NA()) -> 0.32694634 | Z11: -0.88 | AA11: =SQRT(MAX(0,1-Z11^2)) -> 0.47497368 | AB11: =IF(ISNUMBER($B$17),IF(AND($C$17=1,Z11<=-COS(PI()*$B$17)),AA11,NA()),NA()) -> #N/A | AC11: =IF(ISNUMBER($B$17),IF(AND($C$17=2,Z11<=-COS(PI()*$B$17)),AA11,NA()),NA()) -> #N/A | AD11: =IF(ISNUMBER($B$17),IF(AND($C$17=3,Z11<=-COS(PI()*$B$17)),AA11,NA()),NA()) -> #N/A | AE11: =IF(ISNUMBER($B$17),IF(AND($C$17=4,Z11<=-COS(PI()*$B$17)),AA11,NA()),NA()) -> #N/A | AF11: =IF(ISNUMBER($B$17),IF(AND($C$17=5,Z11<=-COS(PI()*$B$17)),AA11,NA()),NA()) -> #N/A | AG11: =IF(ISNUMBER($B$17),IF(AND(ISNUMBER($B$17),Z11>=MIN(0,$Z$2),Z11<=MAX(0,$Z$2)),IF($Z$2=0,0,Z11/$Z$2*$AA$2),NA()),NA()) -> 0.22232228 | AH11: -0.88 | AI11: =SQRT(MAX(0,1-AH11^2)) -> 0.47497368 | AJ11: =IF(ISNUMBER($B$18),IF(AND($C$18=1,AH11<=-COS(PI()*$B$18)),AI11,NA()),NA()) -> 0.47497368 | AK11: =IF(ISNUMBER($B$18),IF(AND($C$18=2,AH11<=-COS(PI()*$B$18)),AI11,NA()),NA()) -> #N/A | AL11: =IF(ISNUMBER($B$18),IF(AND($C$18=3,AH11<=-COS(PI()*$B$18)),AI11,NA()),NA()) -> #N/A | AM11: =IF(ISNUMBER($B$18),IF(AND($C$18=4,AH11<=-COS(PI()*$B$18)),AI11,NA()),NA()) -> #N/A | AN11: =IF(ISNUMBER($B$18),IF(AND($C$18=5,AH11<=-COS(PI()*$B$18)),AI11,NA()),NA()) -> #N/A | AO11: =IF(ISNUMBER($B$18),IF(AND(ISNUMBER($B$18),AH11>=MIN(0,$AH$2),AH11<=MAX(0,$AH$2)),IF($AH$2=0,0,AH11/$AH$2*$AI$2),NA()),NA()) -> #N/A
R12: -0.86 | S12: =SQRT(MAX(0,1-R12^2)) -> 0.51029403 | T12: =IF(ISNUMBER($B$16),IF(AND($C$16=1,R12<=-COS(PI()*$B$16)),S12,NA()),NA()) -> #N/A | U12: =IF(ISNUMBER($B$16),IF(AND($C$16=2,R12<=-COS(PI()*$B$16)),S12,NA()),NA()) -> #N/A | V12: =IF(ISNUMBER($B$16),IF(AND($C$16=3,R12<=-COS(PI()*$B$16)),S12,NA()),NA()) -> #N/A | W12: =IF(ISNUMBER($B$16),IF(AND($C$16=4,R12<=-COS(PI()*$B$16)),S12,NA()),NA()) -> #N/A | X12: =IF(ISNUMBER($B$16),IF(AND($C$16=5,R12<=-COS(PI()*$B$16)),S12,NA()),NA()) -> #N/A | Y12: =IF(ISNUMBER($B$16),IF(AND(ISNUMBER($B$16),R12>=MIN(0,$R$2),R12<=MAX(0,$R$2)),IF($R$2=0,0,R12/$R$2*$S$2),NA()),NA()) -> 0.31951574 | Z12: -0.86 | AA12: =SQRT(MAX(0,1-Z12^2)) -> 0.51029403 | AB12: =IF(ISNUMBER($B$17),IF(AND($C$17=1,Z12<=-COS(PI()*$B$17)),AA12,NA()),NA()) -> #N/A | AC12: =IF(ISNUMBER($B$17),IF(AND($C$17=2,Z12<=-COS(PI()*$B$17)),AA12,NA()),NA()) -> #N/A | AD12: =IF(ISNUMBER($B$17),IF(AND($C$17=3,Z12<=-COS(PI()*$B$17)),AA12,NA()),NA()) -> #N/A | AE12: =IF(ISNUMBER($B$17),IF(AND($C$17=4,Z12<=-COS(PI()*$B$17)),AA12,NA()),NA()) -> #N/A | AF12: =IF(ISNUMBER($B$17),IF(AND($C$17=5,Z12<=-COS(PI()*$B$17)),AA12,NA()),NA()) -> #N/A | AG12: =IF(ISNUMBER($B$17),IF(AND(ISNUMBER($B$17),Z12>=MIN(0,$Z$2),Z12<=MAX(0,$Z$2)),IF($Z$2=0,0,Z12/$Z$2*$AA$2),NA()),NA()) -> 0.2172695 | AH12: -0.86 | AI12: =SQRT(MAX(0,1-AH12^2)) -> 0.51029403 | AJ12: =IF(ISNUMBER($B$18),IF(AND($C$18=1,AH12<=-COS(PI()*$B$18)),AI12,NA()),NA()) -> 0.51029403 | AK12: =IF(ISNUMBER($B$18),IF(AND($C$18=2,AH12<=-COS(PI()*$B$18)),AI12,NA()),NA()) -> #N/A | AL12: =IF(ISNUMBER($B$18),IF(AND($C$18=3,AH12<=-COS(PI()*$B$18)),AI12,NA()),NA()) -> #N/A | AM12: =IF(ISNUMBER($B$18),IF(AND($C$18=4,AH12<=-COS(PI()*$B$18)),AI12,NA()),NA()) -> #N/A | AN12: =IF(ISNUMBER($B$18),IF(AND($C$18=5,AH12<=-COS(PI()*$B$18)),AI12,NA()),NA()) -> #N/A | AO12: =IF(ISNUMBER($B$18),IF(AND(ISNUMBER($B$18),AH12>=MIN(0,$AH$2),AH12<=MAX(0,$AH$2)),IF($AH$2=0,0,AH12/$AH$2*$AI$2),NA()),NA()) -> #N/A
R13: -0.84 | S13: =SQRT(MAX(0,1-R13^2)) -> 0.5425864 | T13: =IF(ISNUMBER($B$16),IF(AND($C$16=1,R13<=-COS(PI()*$B$16)),S13,NA()),NA()) -> #N/A | U13: =IF(ISNUMBER($B$16),IF(AND($C$16=2,R13<=-COS(PI()*$B$16)),S13,NA()),NA()) -> #N/A | V13: =IF(ISNUMBER($B$16),IF(AND($C$16=3,R13<=-COS(PI()*$B$16)),S13,NA()),NA()) -> #N/A | W13: =IF(ISNUMBER($B$16),IF(AND($C$16=4,R13<=-COS(PI()*$B$16)),S13,NA()),NA()) -> #N/A | X13: =IF(ISNUMBER($B$16),IF(AND($C$16=5,R13<=-COS(PI()*$B$16)),S13,NA()),NA()) -> #N/A | Y13: =IF(ISNUMBER($B$16),IF(AND(ISNUMBER($B$16),R13>=MIN(0,$R$2),R13<=MAX(0,$R$2)),IF($R$2=0,0,R13/$R$2*$S$2),NA()),NA()) -> 0.31208514 | Z13: -0.84 | AA13: =SQRT(MAX(0,1-Z13^2)) -> 0.5425864 | AB13: =IF(ISNUMBER($B$17),IF(AND($C$17=1,Z13<=-COS(PI()*$B$17)),AA13,NA()),NA()) -> #N/A | AC13: =IF(ISNUMBER($B$17),IF(AND($C$17=2,Z13<=-COS(PI()*$B$17)),AA13,NA()),NA()) -> #N/A | AD13: =IF(ISNUMBER($B$17),IF(AND($C$17=3,Z13<=-COS(PI()*$B$17)),AA13,NA()),NA()) -> #N/A | AE13: =IF(ISNUMBER($B$17),IF(AND($C$17=4,Z13<=-COS(PI()*$B$17)),AA13,NA()),NA()) -> #N/A | AF13: =IF(ISNUMBER($B$17),IF(AND($C$17=5,Z13<=-COS(PI()*$B$17)),AA13,NA()),NA()) -> #N/A | AG13: =IF(ISNUMBER($B$17),IF(AND(ISNUMBER($B$17),Z13>=MIN(0,$Z$2),Z13<=MAX(0,$Z$2)),IF($Z$2=0,0,Z13/$Z$2*$AA$2),NA()),NA()) -> 0.21221672 | AH13: -0.84 | AI13: =SQRT(MAX(0,1-AH13^2)) -> 0.5425864 | AJ13: =IF(ISNUMBER($B$18),IF(AND($C$18=1,AH13<=-COS(PI()*$B$18)),AI13,NA()),NA()) -> 0.5425864 | AK13: =IF(ISNUMBER($B$18),IF(AND($C$18=2,AH13<=-COS(PI()*$B$18)),AI13,NA()),NA()) -> #N/A | AL13: =IF(ISNUMBER($B$18),IF(AND($C$18=3,AH13<=-COS(PI()*$B$18)),AI13,NA()),NA()) -> #N/A | AM13: =IF(ISNUMBER($B$18),IF(AND($C$18=4,AH13<=-COS(PI()*$B$18)),AI13,NA()),NA()) -> #N/A | AN13: =IF(ISNUMBER($B$18),IF(AND($C$18=5,AH13<=-COS(PI()*$B$18)),AI13,NA()),NA()) -> #N/A | AO13: =IF(ISNUMBER($B$18),IF(AND(ISNUMBER($B$18),AH13>=MIN(0,$AH$2),AH13<=MAX(0,$AH$2)),IF($AH$2=0,0,AH13/$AH$2*$AI$2),NA()),NA()) -> #N/A
R14: -0.82 | S14: =SQRT(MAX(0,1-R14^2)) -> 0.57236352 | T14: =IF(ISNUMBER($B$16),IF(AND($C$16=1,R14<=-COS(PI()*$B$16)),S14,NA()),NA()) -> #N/A | U14: =IF(ISNUMBER($B$16),IF(AND($C$16=2,R14<=-COS(PI()*$B$16)),S14,NA()),NA()) -> #N/A | V14: =IF(ISNUMBER($B$16),IF(AND($C$16=3,R14<=-COS(PI()*$B$16)),S14,NA()),NA()) -> #N/A | W14: =IF(ISNUMBER($B$16),IF(AND($C$16=4,R14<=-COS(PI()*$B$16)),S14,NA()),NA()) -> #N/A | X14: =IF(ISNUMBER($B$16),IF(AND($C$16=5,R14<=-COS(PI()*$B$16)),S14,NA()),NA()) -> #N/A | Y14: =IF(ISNUMBER($B$16),IF(AND(ISNUMBER($B$16),R14>=MIN(0,$R$2),R14<=MAX(0,$R$2)),IF($R$2=0,0,R14/$R$2*$S$2),NA()),NA()) -> 0.30465454 | Z14: -0.82 | AA14: =SQRT(MAX(0,1-Z14^2)) -> 0.57236352 | AB14: =IF(ISNUMBER($B$17),IF(AND($C$17=1,Z14<=-COS(PI()*$B$17)),AA14,NA()),NA()) -> #N/A | AC14: =IF(ISNUMBER($B$17),IF(AND($C$17=2,Z14<=-COS(PI()*$B$17)),AA14,NA()),NA()) -> #N/A | AD14: =IF(ISNUMBER($B$17),IF(AND($C$17=3,Z14<=-COS(PI()*$B$17)),AA14,NA()),NA()) -> #N/A | AE14: =IF(ISNUMBER($B$17),IF(AND($C$17=4,Z14<=-COS(PI()*$B$17)),AA14,NA()),NA()) -> #N/A | AF14: =IF(ISNUMBER($B$17),IF(AND($C$17=5,Z14<=-COS(PI()*$B$17)),AA14,NA()),NA()) -> #N/A | AG14: =IF(ISNUMBER($B$17),IF(AND(ISNUMBER($B$17),Z14>=MIN(0,$Z$2),Z14<=MAX(0,$Z$2)),IF($Z$2=0,0,Z14/$Z$2*$AA$2),NA()),NA()) -> 0.20716394 | AH14: -0.82 | AI14: =SQRT(MAX(0,1-AH14^2)) -> 0.57236352 | AJ14: =IF(ISNUMBER($B$18),IF(AND($C$18=1,AH14<=-COS(PI()*$B$18)),AI14,NA()),NA()) -> #N/A | AK14: =IF(ISNUMBER($B$18),IF(AND($C$18=2,AH14<=-COS(PI()*$B$18)),AI14,NA()),NA()) -> #N/A | AL14: =IF(ISNUMBER($B$18),IF(AND($C$18=3,AH14<=-COS(PI()*$B$18)),AI14,NA()),NA()) -> #N/A | AM14: =IF(ISNUMBER($B$18),IF(AND($C$18=4,AH14<=-COS(PI()*$B$18)),AI14,NA()),NA()) -> #N/A | AN14: =IF(ISNUMBER($B$18),IF(AND($C$18=5,AH14<=-COS(PI()*$B$18)),AI14,NA()),NA()) -> #N/A | AO14: =IF(ISNUMBER($B$18),IF(AND(ISNUMBER($B$18),AH14>=MIN(0,$AH$2),AH14<=MAX(0,$AH$2)),IF($AH$2=0,0,AH14/$AH$2*$AI$2),NA()),NA()) -> 0.56483561
R15: -0.8 | S15: =SQRT(MAX(0,1-R15^2)) -> 0.6 | T15: =IF(ISNUMBER($B$16),IF(AND($C$16=1,R15<=-COS(PI()*$B$16)),S15,NA()),NA()) -> #N/A | U15: =IF(ISNUMBER($B$16),IF(AND($C$16=2,R15<=-COS(PI()*$B$16)),S15,NA()),NA()) -> #N/A | V15: =IF(ISNUMBER($B$16),IF(AND($C$16=3,R15<=-COS(PI()*$B$16)),S15,NA()),NA()) -> #N/A | W15: =IF(ISNUMBER($B$16),IF(AND($C$16=4,R15<=-COS(PI()*$B$16)),S15,NA()),NA()) -> #N/A | X15: =IF(ISNUMBER($B$16),IF(AND($C$16=5,R15<=-COS(PI()*$B$16)),S15,NA()),NA()) -> #N/A | Y15: =IF(ISNUMBER($B$16),IF(AND(ISNUMBER($B$16),R15>=MIN(0,$R$2),R15<=MAX(0,$R$2)),IF($R$2=0,0,R15/$R$2*$S$2),NA()),NA()) -> 0.29722394 | Z15: -0.8 | AA15: =SQRT(MAX(0,1-Z15^2)) -> 0.6 | AB15: =IF(ISNUMBER($B$17),IF(AND($C$17=1,Z15<=-COS(PI()*$B$17)),AA15,NA()),NA()) -> #N/A | AC15: =IF(ISNUMBER($B$17),IF(AND($C$17=2,Z15<=-COS(PI()*$B$17)),AA15,NA()),NA()) -> #N/A | AD15: =IF(ISNUMBER($B$17),IF(AND($C$17=3,Z15<=-COS(PI()*$B$17)),AA15,NA()),NA()) -> #N/A | AE15: =IF(ISNUMBER($B$17),IF(AND($C$17=4,Z15<=-COS(PI()*$B$17)),AA15,NA()),NA()) -> #N/A | AF15: =IF(ISNUMBER($B$17),IF(AND($C$17=5,Z15<=-COS(PI()*$B$17)),AA15,NA()),NA()) -> #N/A | AG15: =IF(ISNUMBER($B$17),IF(AND(ISNUMBER($B$17),Z15>=MIN(0,$Z$2),Z15<=MAX(0,$Z$2)),IF($Z$2=0,0,Z15/$Z$2*$AA$2),NA()),NA()) -> 0.20211116 | AH15: -0.8 | AI15: =SQRT(MAX(0,1-AH15^2)) -> 0.6 | AJ15: =IF(ISNUMBER($B$18),IF(AND($C$18=1,AH15<=-COS(PI()*$B$18)),AI15,NA()),NA()) -> #N/A | AK15: =IF(ISNUMBER($B$18),IF(AND($C$18=2,AH15<=-COS(PI()*$B$18)),AI15,NA()),NA()) -> #N/A | AL15: =IF(ISNUMBER($B$18),IF(AND($C$18=3,AH15<=-COS(PI()*$B$18)),AI15,NA()),NA()) -> #N/A | AM15: =IF(ISNUMBER($B$18),IF(AND($C$18=4,AH15<=-COS(PI()*$B$18)),AI15,NA()),NA()) -> #N/A | AN15: =IF(ISNUMBER($B$18),IF(AND($C$18=5,AH15<=-COS(PI()*$B$18)),AI15,NA()),NA()) -> #N/A | AO15: =IF(ISNUMBER($B$18),IF(AND(ISNUMBER($B$18),AH15>=MIN(0,$AH$2),AH15<=MAX(0,$AH$2)),IF($AH$2=0,0,AH15/$AH$2*$AI$2),NA()),NA()) -> 0.55105913
A16: Overdue Ratio | B16: =IF(B6=0,"n.a.",B7/B6) -> 0.11323077 | C16: =IF(B16<0.2,1,IF(B16<0.3,2,IF(B16<0.45,3,IF(B16<=0.6,4,5)))) -> 1 | R16: -0.78 | S16: =SQRT(MAX(0,1-R16^2)) -> 0.62577951 | T16: =IF(ISNUMBER($B$16),IF(AND($C$16=1,R16<=-COS(PI()*$B$16)),S16,NA()),NA()) -> #N/A | U16: =IF(ISNUMBER($B$16),IF(AND($C$16=2,R16<=-COS(PI()*$B$16)),S16,NA()),NA()) -> #N/A | V16: =IF(ISNUMBER($B$16),IF(AND($C$16=3,R16<=-COS(PI()*$B$16)),S16,NA()),NA()) -> #N/A | W16: =IF(ISNUMBER($B$16),IF(AND($C$16=4,R16<=-COS(PI()*$B$16)),S16,NA()),NA()) -> #N/A | X16: =IF(ISNUMBER($B$16),IF(AND($C$16=5,R16<=-COS(PI()*$B$16)),S16,NA()),NA()) -> #N/A | Y16: =IF(ISNUMBER($B$16),IF(AND(ISNUMBER($B$16),R16>=MIN(0,$R$2),R16<=MAX(0,$R$2)),IF($R$2=0,0,R16/$R$2*$S$2),NA()),NA()) -> 0.28979335 | Z16: -0.78 | AA16: =SQRT(MAX(0,1-Z16^2)) -> 0.62577951 | AB16: =IF(ISNUMBER($B$17),IF(AND($C$17=1,Z16<=-COS(PI()*$B$17)),AA16,NA()),NA()) -> #N/A | AC16: =IF(ISNUMBER($B$17),IF(AND($C$17=2,Z16<=-COS(PI()*$B$17)),AA16,NA()),NA()) -> #N/A | AD16: =IF(ISNUMBER($B$17),IF(AND($C$17=3,Z16<=-COS(PI()*$B$17)),AA16,NA()),NA()) -> #N/A | AE16: =IF(ISNUMBER($B$17),IF(AND($C$17=4,Z16<=-COS(PI()*$B$17)),AA16,NA()),NA()) -> #N/A | AF16: =IF(ISNUMBER($B$17),IF(AND($C$17=5,Z16<=-COS(PI()*$B$17)),AA16,NA()),NA()) -> #N/A | AG16: =IF(ISNUMBER($B$17),IF(AND(ISNUMBER($B$17),Z16>=MIN(0,$Z$2),Z16<=MAX(0,$Z$2)),IF($Z$2=0,0,Z16/$Z$2*$AA$2),NA()),NA()) -> 0.19705838 | AH16: -0.78 | AI16: =SQRT(MAX(0,1-AH16^2)) -> 0.62577951 | AJ16: =IF(ISNUMBER($B$18),IF(AND($C$18=1,AH16<=-COS(PI()*$B$18)),AI16,NA()),NA()) -> #N/A | AK16: =IF(ISNUMBER($B$18),IF(AND($C$18=2,AH16<=-COS(PI()*$B$18)),AI16,NA()),NA()) -> #N/A | AL16: =IF(ISNUMBER($B$18),IF(AND($C$18=3,AH16<=-COS(PI()*$B$18)),AI16,NA()),NA()) -> #N/A | AM16: =IF(ISNUMBER($B$18),IF(AND($C$18=4,AH16<=-COS(PI()*$B$18)),AI16,NA()),NA()) -> #N/A | AN16: =IF(ISNUMBER($B$18),IF(AND($C$18=5,AH16<=-COS(PI()*$B$18)),AI16,NA()),NA()) -> #N/A | AO16: =IF(ISNUMBER($B$18),IF(AND(ISNUMBER($B$18),AH16>=MIN(0,$AH$2),AH16<=MAX(0,$AH$2)),IF($AH$2=0,0,AH16/$AH$2*$AI$2),NA()),NA()) -> 0.53728265
